Workbook

Sheet Exclusive
E1: =F1-#REF!+1 -> #REF! | F1: =TODAY()-1 -> 46309 | J1: =SUBTOTAL(9,J3:J302) -> 166 | K1: =SUBTOTAL(9,K3:K302) -> 160.6 | L1: =SUBTOTAL(9,L3:L302) -> 234.9 | M1: =SUBTOTAL(9,M3:M302) -> 160
A2: REGION | B2: AREA | C2: CODE | D2: SAP | E2: DEALERS NAME | F2: DOA | G2: EXCLUSIVE DEALER | H2: ZERO | I2: EXCLUSIVE DEALER | J2: OCT | K2: Nov | L2: Dec | M2: Jan
A3: NE 1 | B3: NAGAON | C3: S078 | D3: 1000000673 | E3: SREE BHANDER (SP FIRM) | F3: 38490 | G3: EXCLUSIVE DEALER | H3: 0 | I3: =IF(G3>0,1,0) -> 1 | J3: 1220 | K3: 1557.5 | L3: 1727.5 | M3: 2210
A4: NE 1 | B4: NAGAON | C4: R096 | D4: 1000000665 | E4: RAFIK HARDWARE | F4: 40672 | G4: EXCLUSIVE DEALER | H4: 0 | I4: =IF(G4>0,1,0) -> 1 | J4: 365 | K4: 300 | L4: 222 | M4: 340
A5: NE 1 | B5: NAGAON | C5: NEA028 | D5: 1000000633 | E5: A. HAQUE HARDWARE | F5: 42048 | G5: EXCLUSIVE DEALER | H5: 0 | I5: =IF(G5>0,1,0) -> 1 | J5: 60 | K5: 115 | L5: 115 | M5: 163
A6: NE 1 | B6: NAGAON | C6: NES132 | D6: 1000000672 | E6: SHARMA HARDWARE (NAGAON) | F6: 42448 | G6: EXCLUSIVE DEALER | H6: 0 | I6: =IF(G6>0,1,0) -> 1 | J6: 20 | K6: 20 | L6: 20 | M6: 30
A7: NE 1 | B7: NAGAON | C7: NEH035 | D7: 1000000647 | E7: HARIOM HARDWARE (DHING) | F7: 42842 | G7: EXCLUSIVE DEALER | H7: 0 | I7: =IF(G7>0,1,0) -> 1 | J7: 88.5 | K7: 121 | L7: 139 | M7: 139
A8: NE 1 | B8: NAGAON | C8: NES190 | D8: 1000000667 | E8: S K TRADING CO. (LUMDING) | F8: 42849 | G8: EXCLUSIVE DEALER | H8: 0 | I8: =IF(G8>0,1,0) -> 1 | J8: 145 | K8: 189.5 | L8: 132 | M8: 140
A9: NE 1 | B9: NAGAON | C9: NEH047 | D9: 1000000646 | E9: HANUMAN BHANDAR (BOKOLIA) | F9: 43132 | G9: EXCLUSIVE DEALER | H9: 0 | I9: =IF(G9>0,1,0) -> 1 | J9: 420 | K9: 200 | L9: 360 | M9: 210
A10: NE 1 | B10: NAGAON | C10: NES262 | D10: 1000000670 | E10: SANDHYA HARDWARE (JAMUNAMUKH) | F10: 43154 | G10: EXCLUSIVE DEALER | H10: 0 | I10: =IF(G10>0,1,0) -> 1 | J10: 410 | K10: 490 | L10: 460 | M10: 560
A11: NE 1 | B11: NAGAON | C11: NEM194 | D11: 1000000659 | E11: MUSTAKIM HARDWARE | F11: 43258 | G11: EXCLUSIVE DEALER | H11: 0 | I11: =IF(G11>0,1,0) -> 1 | J11: 76 | K11: 64.5 | L11: 62.5 | M11: 65
A12: NE 1 | B12: NAGAON | C12: NEA209 | D12: 1000000637 | E12: AYUSH HARDWARE | F12: 43294 | G12: EXCLUSIVE DEALER | H12: 0 | I12: =IF(G12>0,1,0) -> 1 | J12: 60 | K12: 80 | L12: 100 | M12: 90
A13: NE 1 | B13: NAGAON | C13: NEM230 | D13: 1000000658 | E13: MI HARDWARE & CEMENT | F13: 43495 | G13: EXCLUSIVE DEALER | H13: 0 | I13: =IF(G13>0,1,0) -> 1 | J13: 480 | K13: 840 | L13: 870 | M13: 490
A14: NE 1 | B14: NAGAON | C14: NEM242 | D14: 1000001037 | E14: MAA TRADERS (BOKAJAN) | F14: 43623 | G14: EXCLUSIVE DEALER | H14: 0 | I14: =IF(G14>0,1,0) -> 1 | J14: 2040 | K14: 2960 | L14: 2535 | M14: 2920
... A299: NE 1 | B299: N C Hills | C299: NEN234 | D299: 1000004155 | E299: NATH VARIETY STORE | F299: 45588 | G299: EXCLUSIVE DEALER | H299: 0 | I299: =IF(G299>0,1,0) -> 1 | J299: 50 | K299: 145 | L299: 92 | M299: 88
A300: NE 1 | B300: MANIPUR | C300: H132 | D300: 1000000568 | E300: HOLISTIC ENTERPRISES | F300: 44738 | G300: EXCLUSIVE DEALER | H300: 1 | J300: 0 | K300: 37 | L300: 172 | M300: 105
A301: NE 1 | B301: MANIPUR | C301: G141 | D301: 1000000566 | E301: GOPAL ENTERPRISES | F301: 41737 | G301: EXCLUSIVE DEALER | H301: 1 | J301: 0 | K301: 0 | L301: 0 | M301: 152
A302: NE 1 | B302: MANIPUR | C302: T053 | D302: 1000000580 | E302: THANGJING HARDWARE | F302: 44738 | G302: EXCLUSIVE DEALER | H302: 0 | J302: 0 | K302: 0 | L302: 0 | M302: 55

Sheet SUMMARY-M
B1: DEALER PERFORMANCE SUMMARY (Dec'25)
B2: 46021 | G2: <=15% mark red | I2: >=50% mark red | K2: >=50% mark red | P2: >=50% mark red | Q2: =B2-1 -> 46020
B3: AREA | C3: ASM | D3: RSM | E3: TOTAL SALE | F3: PREMIUM SALE | G3: PREMIUM % | H3: DEGROWTH DEALER (Nov'25 VS Oct'25) (NOS) | I3: % of DEGROWING DEALERS (Nov'25 VS Oct'24) | J3: DEGROWTH DEALER (Nov'25 VS Nov'24) (NOS) | K3: % of DEGROWING DEALERS (Nov'25 VS Nov''24) | L3: TOTAL DEALER (NOS) | M3: EXCLUSIVE DEALERS (NOS) | N3: Targeted Dealer Nos (Nov-25) | O3: ZERO LIFTERS (NOS) | P3: % of ZERO LIFTERS | Q3: ZERO LIFTERS (NOS) | R3: ZERO LIFTERS Increase/ Decrease (NOS) | S3: Zero lifters in Nov'25 & <30 MT lifted in Oct'25 | T3: Zero lifters in Nov'25 & >=30 MT lifted in Oct'25
B4: NAGAON | C4: SANJEEV BARMAN | D4: VIKASH KUMAR | G4: =IFERROR(F4/E4,0) -> 0 | H4: =COUNTIFS(DLRWISE!S:S,"DEGROWTH",DLRWISE!B:B,'SUMMARY-M'!B4) -> 10 | I4: =H4/$L4 -> 0.27777778 | J4: =COUNTIFS(DLRWISE!Y:Y,"DEGROWTH",DLRWISE!B:B,'SUMMARY-M'!B4) -> 16 | K4: =J4/$L4 -> 0.44444444 | L4: =COUNTIFS(DLRWISE!B:B,'SUMMARY-M'!B4) -> 36 | M4: =COUNTIFS(DLRWISE!B:B,'SUMMARY-M'!B4,DLRWISE!H:H,DLRWISE!$H$2) -> 0 | N4: =COUNTIFS(DLRWISE!G:G,DLRWISE!$G$2,DLRWISE!B:B,'SUMMARY-M'!B4) -> 31 | O4: =COUNTIFS(DLRWISE!B:B,'SUMMARY-M'!B4,DLRWISE!K:K,"<="&0) -> 7 | P4: =O4/L4 -> 0.19444444 | Q4: =SUMIF(DLRWISE!B:B,'SUMMARY-M'!B4,DLRWISE!Z:Z) -> 3 | R4: =O4-Q4 -> 4 | S4: =COUNTIFS(DLRWISE!B:B,'SUMMARY-M'!B4,DLRWISE!K:K,0,DLRWISE!N:N,"<"&30) -> 7 | T4: =O4-S4 -> 0
B5: HOJAI | C5: SANJEEV BARMAN | D5: VIKASH KUMAR | G5: =IFERROR(F5/E5,0) -> 0 | H5: =COUNTIFS(DLRWISE!S:S,"DEGROWTH",DLRWISE!B:B,'SUMMARY-M'!B5) -> 14 | I5: =H5/$L5 -> 0.42424242 | J5: =COUNTIFS(DLRWISE!Y:Y,"DEGROWTH",DLRWISE!B:B,'SUMMARY-M'!B5) -> 16 | K5: =J5/$L5 -> 0.48484848 | L5: =COUNTIFS(DLRWISE!B:B,'SUMMARY-M'!B5) -> 33 | M5: =COUNTIFS(DLRWISE!B:B,'SUMMARY-M'!B5,DLRWISE!H:H,DLRWISE!$H$2) -> 0 | N5: =COUNTIFS(DLRWISE!G:G,DLRWISE!$G$2,DLRWISE!B:B,'SUMMARY-M'!B5) -> 33 | O5: =COUNTIFS(DLRWISE!B:B,'SUMMARY-M'!B5,DLRWISE!K:K,"<="&0) -> 2 | P5: =O5/L5 -> 0.060606061 | Q5: =SUMIF(DLRWISE!B:B,'SUMMARY-M'!B5,DLRWISE!Z:Z) -> 0 | R5: =O5-Q5 -> 2 | S5: =COUNTIFS(DLRWISE!B:B,'SUMMARY-M'!B5,DLRWISE!K:K,0,DLRWISE!N:N,"<"&30) -> 2 | T5: =O5-S5 -> 0
B6: KARBIANGLONG | C6: SANJEEV BARMAN | D6: VIKASH KUMAR | G6: =IFERROR(F6/E6,0) -> 0 | H6: =COUNTIFS(DLRWISE!S:S,"DEGROWTH",DLRWISE!B:B,'SUMMARY-M'!B6) -> 9 | I6: =H6/$L6 -> 0.47368421 | J6: =COUNTIFS(DLRWISE!Y:Y,"DEGROWTH",DLRWISE!B:B,'SUMMARY-M'!B6) -> 10 | K6: =J6/$L6 -> 0.52631579 | L6: =COUNTIFS(DLRWISE!B:B,'SUMMARY-M'!B6) -> 19 | M6: =COUNTIFS(DLRWISE!B:B,'SUMMARY-M'!B6,DLRWISE!H:H,DLRWISE!$H$2) -> 0 | N6: =COUNTIFS(DLRWISE!G:G,DLRWISE!$G$2,DLRWISE!B:B,'SUMMARY-M'!B6) -> 18 | O6: =COUNTIFS(DLRWISE!B:B,'SUMMARY-M'!B6,DLRWISE!K:K,"<="&0) -> 1 | P6: =O6/L6 -> 0.052631579 | Q6: =SUMIF(DLRWISE!B:B,'SUMMARY-M'!B6,DLRWISE!Z:Z) -> 0 | R6: =O6-Q6 -> 1 | S6: =COUNTIFS(DLRWISE!B:B,'SUMMARY-M'!B6,DLRWISE!K:K,0,DLRWISE!N:N,"<"&30) -> 1 | T6: =O6-S6 -> 0
B7: N C HILLS | C7: SANJEEV BARMAN | D7: VIKASH KUMAR | G7: =IFERROR(F7/E7,0) -> 0 | H7: =COUNTIFS(DLRWISE!S:S,"DEGROWTH",DLRWISE!B:B,'SUMMARY-M'!B7) -> 8 | I7: =H7/L7 -> 0.53333333 | J7: =COUNTIFS(DLRWISE!Y:Y,"DEGROWTH",DLRWISE!B:B,'SUMMARY-M'!B7) -> 6 | K7: =J7/$L7 -> 0.4 | L7: =COUNTIFS(DLRWISE!B:B,'SUMMARY-M'!B7) -> 15 | M7: =COUNTIFS(DLRWISE!B:B,'SUMMARY-M'!B7,DLRWISE!H:H,DLRWISE!$H$2) -> 0 | N7: =COUNTIFS(DLRWISE!G:G,DLRWISE!$G$2,DLRWISE!B:B,'SUMMARY-M'!B7) -> 15 | O7: =COUNTIFS(DLRWISE!B:B,'SUMMARY-M'!B7,DLRWISE!K:K,"<="&0) -> 1 | P7: =O7/L7 -> 0.066666667 | Q7: =SUMIF(DLRWISE!B:B,'SUMMARY-M'!B7,DLRWISE!Z:Z) -> 1 | R7: =O7-Q7 -> 0 | S7: =COUNTIFS(DLRWISE!B:B,'SUMMARY-M'!B7,DLRWISE!K:K,0,DLRWISE!N:N,"<"&30) -> 1 | T7: =O7-S7 -> 0
B8: TEZPUR | C8: PRAKASH GHIMRE | D8: VIKASH KUMAR | G8: =IFERROR(F8/E8,0) -> 0 | H8: =COUNTIFS(DLRWISE!S:S,"DEGROWTH",DLRWISE!B:B,'SUMMARY-M'!B8) -> 11 | I8: =H8/L8 -> 0.32352941 | J8: =COUNTIFS(DLRWISE!Y:Y,"DEGROWTH",DLRWISE!B:B,'SUMMARY-M'!B8) -> 12 | K8: =J8/$L8 -> 0.35294118 | L8: =COUNTIFS(DLRWISE!B:B,'SUMMARY-M'!B8) -> 34 | M8: =COUNTIFS(DLRWISE!B:B,'SUMMARY-M'!B8,DLRWISE!H:H,DLRWISE!$H$2) -> 0 | N8: =COUNTIFS(DLRWISE!G:G,DLRWISE!$G$2,DLRWISE!B:B,'SUMMARY-M'!B8) -> 34 | O8: =COUNTIFS(DLRWISE!B:B,'SUMMARY-M'!B8,DLRWISE!K:K,"<="&0) -> 1 | P8: =O8/L8 -> 0.029411765 | Q8: =SUMIF(DLRWISE!B:B,'SUMMARY-M'!B8,DLRWISE!Z:Z) -> 3 | R8: =O8-Q8 -> -2 | S8: =COUNTIFS(DLRWISE!B:B,'SUMMARY-M'!B8,DLRWISE!K:K,0,DLRWISE!N:N,"<"&30) -> 0 | T8: =O8-S8 -> 1
B9: BISWANATH | C9: PRAKASH GHIMRE | D9: VIKASH KUMAR | G9: =IFERROR(F9/E9,0) -> 0 | H9: =COUNTIFS(DLRWISE!S:S,"DEGROWTH",DLRWISE!B:B,'SUMMARY-M'!B9) -> 7 | I9: =H9/L9 -> 0.36842105 | J9: =COUNTIFS(DLRWISE!Y:Y,"DEGROWTH",DLRWISE!B:B,'SUMMARY-M'!B9) -> 10 | K9: =J9/$L9 -> 0.52631579 | L9: =COUNTIFS(DLRWISE!B:B,'SUMMARY-M'!B9) -> 19 | M9: =COUNTIFS(DLRWISE!B:B,'SUMMARY-M'!B9,DLRWISE!H:H,DLRWISE!$H$2) -> 0 | N9: =COUNTIFS(DLRWISE!G:G,DLRWISE!$G$2,DLRWISE!B:B,'SUMMARY-M'!B9) -> 19 | O9: =COUNTIFS(DLRWISE!B:B,'SUMMARY-M'!B9,DLRWISE!K:K,"<="&0) -> 0 | P9: =O9/L9 -> 0 | Q9: =SUMIF(DLRWISE!B:B,'SUMMARY-M'!B9,DLRWISE!Z:Z) -> 1 | R9: =O9-Q9 -> -1 | S9: =COUNTIFS(DLRWISE!B:B,'SUMMARY-M'!B9,DLRWISE!K:K,0,DLRWISE!N:N,"<"&30) -> 0 | T9: =O9-S9 -> 0
B10: LAKHIMPUR | C10: VACANT ASM NLP | D10: VIKASH KUMAR | G10: =IFERROR(F10/E10,0) -> 0 | H10: =COUNTIFS(DLRWISE!S:S,"DEGROWTH",DLRWISE!B:B,'SUMMARY-M'!B10) -> 15 | I10: =H10/L10 -> 0.44117647 | J10: =COUNTIFS(DLRWISE!Y:Y,"DEGROWTH",DLRWISE!B:B,'SUMMARY-M'!B10) -> 14 | K10: =J10/$L10 -> 0.41176471 | L10: =COUNTIFS(DLRWISE!B:B,'SUMMARY-M'!B10) -> 34 | M10: =COUNTIFS(DLRWISE!B:B,'SUMMARY-M'!B10,DLRWISE!H:H,DLRWISE!$H$2) -> 0 | N10: =COUNTIFS(DLRWISE!G:G,DLRWISE!$G$2,DLRWISE!B:B,'SUMMARY-M'!B10) -> 33 | O10: =COUNTIFS(DLRWISE!B:B,'SUMMARY-M'!B10,DLRWISE!K:K,"<="&0) -> 7 | P10: =O10/L10 -> 0.20588235 | Q10: =SUMIF(DLRWISE!B:B,'SUMMARY-M'!B10,DLRWISE!Z:Z) -> 8 | R10: =O10-Q10 -> -1 | S10: =COUNTIFS(DLRWISE!B:B,'SUMMARY-M'!B10,DLRWISE!K:K,0,DLRWISE!N:N,"<"&30) -> 5 | T10: =O10-S10 -> 2
B11: DHEMAJI | C11: VACANT ASM DHEMAJI | D11: VIKASH KUMAR | G11: =IFERROR(F11/E11,0) -> 0 | H11: =COUNTIFS(DLRWISE!S:S,"DEGROWTH",DLRWISE!B:B,'SUMMARY-M'!B11) -> 10 | I11: =H11/L11 -> 0.33333333 | J11: =COUNTIFS(DLRWISE!Y:Y,"DEGROWTH",DLRWISE!B:B,'SUMMARY-M'!B11) -> 13 | K11: =J11/$L11 -> 0.43333333 | L11: =COUNTIFS(DLRWISE!B:B,'SUMMARY-M'!B11) -> 30 | M11: =COUNTIFS(DLRWISE!B:B,'SUMMARY-M'!B11,DLRWISE!H:H,DLRWISE!$H$2) -> 0 | N11: =COUNTIFS(DLRWISE!G:G,DLRWISE!$G$2,DLRWISE!B:B,'SUMMARY-M'!B11) -> 28 | O11: =COUNTIFS(DLRWISE!B:B,'SUMMARY-M'!B11,DLRWISE!K:K,"<="&0) -> 5 | P11: =O11/L11 -> 0.16666667 | Q11: =SUMIF(DLRWISE!B:B,'SUMMARY-M'!B11,DLRWISE!Z:Z) -> 2 | R11: =O11-Q11 -> 3 | S11: =COUNTIFS(DLRWISE!B:B,'SUMMARY-M'!B11,DLRWISE!K:K,0,DLRWISE!N:N,"<"&30) -> 3 | T11: =O11-S11 -> 2
B12: AP- BANDERDEWA | C12: SATYAJIT SAHA | D12: VIKASH KUMAR | G12: =IFERROR(F12/E12,0) -> 0 | H12: =COUNTIFS(DLRWISE!S:S,"DEGROWTH",DLRWISE!B:B,'SUMMARY-M'!B12) -> 14 | I12: =H12/L12 -> 0.46666667 | J12: =COUNTIFS(DLRWISE!Y:Y,"DEGROWTH",DLRWISE!B:B,'SUMMARY-M'!B12) -> 15 | K12: =J12/$L12 -> 0.5 | L12: =COUNTIFS(DLRWISE!B:B,'SUMMARY-M'!B12) -> 30 | M12: =COUNTIFS(DLRWISE!B:B,'SUMMARY-M'!B12,DLRWISE!H:H,DLRWISE!$H$2) -> 0 | N12: =COUNTIFS(DLRWISE!G:G,DLRWISE!$G$2,DLRWISE!B:B,'SUMMARY-M'!B12) -> 28 | O12: =COUNTIFS(DLRWISE!B:B,'SUMMARY-M'!B12,DLRWISE!K:K,"<="&0) -> 7 | P12: =O12/L12 -> 0.23333333 | Q12: =SUMIF(DLRWISE!B:B,'SUMMARY-M'!B12,DLRWISE!Z:Z) -> 2 | R12: =O12-Q12 -> 5 | S12: =COUNTIFS(DLRWISE!B:B,'SUMMARY-M'!B12,DLRWISE!K:K,0,DLRWISE!N:N,"<"&30) -> 6 | T12: =O12-S12 -> 1
B13: AP- LEKHABALI | C13: SATYAJIT SAHA | D13: VIKASH KUMAR | G13: =IFERROR(F13/E13,0) -> 0 | H13: =COUNTIFS(DLRWISE!S:S,"DEGROWTH",DLRWISE!B:B,'SUMMARY-M'!B13) -> 19 | I13: =H13/L13 -> 0.45238095 | J13: =COUNTIFS(DLRWISE!Y:Y,"DEGROWTH",DLRWISE!B:B,'SUMMARY-M'!B13) -> 16 | K13: =J13/$L13 -> 0.38095238 | L13: =COUNTIFS(DLRWISE!B:B,'SUMMARY-M'!B13) -> 42 | M13: =COUNTIFS(DLRWISE!B:B,'SUMMARY-M'!B13,DLRWISE!H:H,DLRWISE!$H$2) -> 0 | N13: =COUNTIFS(DLRWISE!G:G,DLRWISE!$G$2,DLRWISE!B:B,'SUMMARY-M'!B13) -> 36 | O13: =COUNTIFS(DLRWISE!B:B,'SUMMARY-M'!B13,DLRWISE!K:K,"<="&0) -> 8 | P13: =O13/L13 -> 0.19047619 | Q13: =SUMIF(DLRWISE!B:B,'SUMMARY-M'!B13,DLRWISE!Z:Z) -> 1 | R13: =O13-Q13 -> 7 | S13: =COUNTIFS(DLRWISE!B:B,'SUMMARY-M'!B13,DLRWISE!K:K,0,DLRWISE!N:N,"<"&30) -> 7 | T13: =O13-S13 -> 1
B14: JORHAT | C14: NIRANJAN MANDAL | D14: SUBHASISH BHOWMIK | G14: =IFERROR(F14/E14,0) -> 0 | H14: =COUNTIFS(DLRWISE!S:S,"DEGROWTH",DLRWISE!B:B,'SUMMARY-M'!B14) -> 17 | I14: =H14/L14 -> 0.44736842 | J14: =COUNTIFS(DLRWISE!Y:Y,"DEGROWTH",DLRWISE!B:B,'SUMMARY-M'!B14) -> 14 | K14: =J14/$L14 -> 0.36842105 | L14: =COUNTIFS(DLRWISE!B:B,'SUMMARY-M'!B14) -> 38 | M14: =COUNTIFS(DLRWISE!B:B,'SUMMARY-M'!B14,DLRWISE!H:H,DLRWISE!$H$2) -> 0 | N14: =COUNTIFS(DLRWISE!G:G,DLRWISE!$G$2,DLRWISE!B:B,'SUMMARY-M'!B14) -> 34 | O14: =COUNTIFS(DLRWISE!B:B,'SUMMARY-M'!B14,DLRWISE!K:K,"<="&0) -> 7 | P14: =O14/L14 -> 0.18421053 | Q14: =SUMIF(DLRWISE!B:B,'SUMMARY-M'!B14,DLRWISE!Z:Z) -> 4 | R14: =O14-Q14 -> 3 | S14: =COUNTIFS(DLRWISE!B:B,'SUMMARY-M'!B14,DLRWISE!K:K,0,DLRWISE!N:N,"<"&30) -> 4 | T14: =O14-S14 -> 3
B15: GOLAGHAT | C15: NIRANJAN MANDAL | D15: SUBHASISH BHOWMIK | G15: =IFERROR(F15/E15,0) -> 0 | H15: =COUNTIFS(DLRWISE!S:S,"DEGROWTH",DLRWISE!B:B,'SUMMARY-M'!B15) -> 7 | I15: =H15/L15 -> 0.28 | J15: =COUNTIFS(DLRWISE!Y:Y,"DEGROWTH",DLRWISE!B:B,'SUMMARY-M'!B15) -> 10 | K15: =J15/$L15 -> 0.4 | L15: =COUNTIFS(DLRWISE!B:B,'SUMMARY-M'!B15) -> 25 | M15: =COUNTIFS(DLRWISE!B:B,'SUMMARY-M'!B15,DLRWISE!H:H,DLRWISE!$H$2) -> 0 | N15: =COUNTIFS(DLRWISE!G:G,DLRWISE!$G$2,DLRWISE!B:B,'SUMMARY-M'!B15) -> 23 | O15: =COUNTIFS(DLRWISE!B:B,'SUMMARY-M'!B15,DLRWISE!K:K,"<="&0) -> 7 | P15: =O15/L15 -> 0.28 | Q15: =SUMIF(DLRWISE!B:B,'SUMMARY-M'!B15,DLRWISE!Z:Z) -> 6 | R15: =O15-Q15 -> 1 | S15: =COUNTIFS(DLRWISE!B:B,'SUMMARY-M'!B15,DLRWISE!K:K,0,DLRWISE!N:N,"<"&30) -> 5 | T15: =O15-S15 -> 2
B16: SIBSAGAR | C16: SUJIT SAXENA | D16: SUBHASISH BHOWMIK | G16: =IFERROR(F16/E16,0) -> 0 | H16: =COUNTIFS(DLRWISE!S:S,"DEGROWTH",DLRWISE!B:B,'SUMMARY-M'!B16) -> 10 | I16: =H16/L16 -> 0.35714286 | J16: =COUNTIFS(DLRWISE!Y:Y,"DEGROWTH",DLRWISE!B:B,'SUMMARY-M'!B16) -> 8 | K16: =J16/$L16 -> 0.28571429 | L16: =COUNTIFS(DLRWISE!B:B,'SUMMARY-M'!B16) -> 28 | M16: =COUNTIFS(DLRWISE!B:B,'SUMMARY-M'!B16,DLRWISE!H:H,DLRWISE!$H$2) -> 0 | N16: =COUNTIFS(DLRWISE!G:G,DLRWISE!$G$2,DLRWISE!B:B,'SUMMARY-M'!B16) -> 27 | O16: =COUNTIFS(DLRWISE!B:B,'SUMMARY-M'!B16,DLRWISE!K:K,"<="&0) -> 4 | P16: =O16/L16 -> 0.14285714 | Q16: =SUMIF(DLRWISE!B:B,'SUMMARY-M'!B16,DLRWISE!Z:Z) -> 1 | R16: =O16-Q16 -> 3 | S16: =COUNTIFS(DLRWISE!B:B,'SUMMARY-M'!B16,DLRWISE!K:K,0,DLRWISE!N:N,"<"&30) -> 2 | T16: =O16-S16 -> 2
B17: DIBRUGARH | C17: MANOJ CHETRY | D17: SUBHASISH BHOWMIK | G17: =IFERROR(F17/E17,0) -> 0 | H17: =COUNTIFS(DLRWISE!S:S,"DEGROWTH",DLRWISE!B:B,'SUMMARY-M'!B17) -> 24 | I17: =H17/L17 -> 0.46153846 | J17: =COUNTIFS(DLRWISE!Y:Y,"DEGROWTH",DLRWISE!B:B,'SUMMARY-M'!B17) -> 28 | K17: =J17/$L17 -> 0.53846154 | L17: =COUNTIFS(DLRWISE!B:B,'SUMMARY-M'!B17) -> 52 | M17: =COUNTIFS(DLRWISE!B:B,'SUMMARY-M'!B17,DLRWISE!H:H,DLRWISE!$H$2) -> 0 | N17: =COUNTIFS(DLRWISE!G:G,DLRWISE!$G$2,DLRWISE!B:B,'SUMMARY-M'!B17) -> 49 | O17: =COUNTIFS(DLRWISE!B:B,'SUMMARY-M'!B17,DLRWISE!K:K,"<="&0) -> 7 | P17: =O17/L17 -> 0.13461538 | Q17: =SUMIF(DLRWISE!B:B,'SUMMARY-M'!B17,DLRWISE!Z:Z) -> 8 | R17: =O17-Q17 -> -1 | S17: =COUNTIFS(DLRWISE!B:B,'SUMMARY-M'!B17,DLRWISE!K:K,0,DLRWISE!N:N,"<"&30) -> 7 | T17: =O17-S17 -> 0
B18: AP- TINSUKIA SIDE | C18: RAJU UDADHYAYA | D18: SUBHASISH BHOWMIK | G18: =IFERROR(F18/E18,0) -> 0 | H18: =COUNTIFS(DLRWISE!S:S,"DEGROWTH",DLRWISE!B:B,'SUMMARY-M'!B18) -> 3 | I18: =H18/L18 -> 0.25 | J18: =COUNTIFS(DLRWISE!Y:Y,"DEGROWTH",DLRWISE!B:B,'SUMMARY-M'!B18) -> 2 | K18: =J18/$L18 -> 0.16666667 | L18: =COUNTIFS(DLRWISE!B:B,'SUMMARY-M'!B18) -> 12 | M18: =COUNTIFS(DLRWISE!B:B,'SUMMARY-M'!B18,DLRWISE!H:H,DLRWISE!$H$2) -> 0 | N18: =COUNTIFS(DLRWISE!G:G,DLRWISE!$G$2,DLRWISE!B:B,'SUMMARY-M'!B18) -> 11 | O18: =COUNTIFS(DLRWISE!B:B,'SUMMARY-M'!B18,DLRWISE!K:K,"<="&0) -> 3 | P18: =O18/L18 -> 0.25 | Q18: =SUMIF(DLRWISE!B:B,'SUMMARY-M'!B18,DLRWISE!Z:Z) -> 1 | R18: =O18-Q18 -> 2 | S18: =COUNTIFS(DLRWISE!B:B,'SUMMARY-M'!B18,DLRWISE!K:K,0,DLRWISE!N:N,"<"&30) -> 3 | T18: =O18-S18 -> 0
... B23: NAGALAND | C23: ROBIN LIMBU | D23: BASUDEV ROY | G23: =IFERROR(F23/E23,0) -> 0 | H23: =COUNTIFS(DLRWISE!S:S,"DEGROWTH",DLRWISE!B:B,'SUMMARY-M'!B23) -> 16 | I23: =H23/L23 -> 0.5 | J23: =COUNTIFS(DLRWISE!Y:Y,"DEGROWTH",DLRWISE!B:B,'SUMMARY-M'!B23) -> 15 | K23: =J23/$L23 -> 0.46875 | L23: =COUNTIFS(DLRWISE!B:B,'SUMMARY-M'!B23) -> 32 | M23: =COUNTIFS(DLRWISE!B:B,'SUMMARY-M'!B23,DLRWISE!H:H,DLRWISE!$H$2) -> 0 | N23: =COUNTIFS(DLRWISE!G:G,DLRWISE!$G$2,DLRWISE!B:B,'SUMMARY-M'!B23) -> 29 | O23: =COUNTIFS(DLRWISE!B:B,'SUMMARY-M'!B23,DLRWISE!K:K,"<="&0) -> 9 | P23: =O23/L23 -> 0.28125 | Q23: =SUMIF(DLRWISE!B:B,'SUMMARY-M'!B23,DLRWISE!Z:Z) -> 5 | R23: =O23-Q23 -> 4 | S23: =COUNTIFS(DLRWISE!B:B,'SUMMARY-M'!B23,DLRWISE!K:K,0,DLRWISE!N:N,"<"&30) -> 6 | T23: =O23-S23 -> 3
B24: NE 1 TOTAL | E24: =SUM(E4:E23) -> 0 | F24: =SUM(F4:F23) -> 0 | G24: =F24/E24 -> #DIV/0! | H24: =SUM(H4:H23) -> 248 | I24: =H24/L24 -> 0.40722496 | J24: =SUM(J4:J23) -> 259 | K24: =J24/$L24 -> 0.42528736 | L24: =SUM(L4:L23) -> 609 | M24: =SUM(M4:M23) -> 0 | N24: =SUM(N4:N23) -> 565 | O24: =SUM(O4:O23) -> 100 | P24: =O24/L24 -> 0.16420361 | Q24: =SUM(Q4:Q23) -> 63 | R24: =O24-Q24 -> 37 | S24: =SUM(S4:S23) -> 74 | T24: =O24-S24 -> 26
B25: GUWAHATI RURAL | C25: SUBHASH ARJEL | D25: SAURABH KUMAR | G25: =IFERROR(F25/E25,0) -> 0 | H25: =COUNTIFS(DLRWISE!S:S,"DEGROWTH",DLRWISE!B:B,'SUMMARY-M'!B25) -> 25 | I25: =H25/L25 -> 0.5 | J25: =COUNTIFS(DLRWISE!Y:Y,"DEGROWTH",DLRWISE!B:B,'SUMMARY-M'!B25) -> 23 | K25: =J25/$L25 -> 0.46 | L25: =COUNTIFS(DLRWISE!B:B,'SUMMARY-M'!B25) -> 50 | M25: =COUNTIFS(DLRWISE!B:B,'SUMMARY-M'!B25,DLRWISE!H:H,DLRWISE!$H$2) -> 0 | N25: =COUNTIFS(DLRWISE!G:G,DLRWISE!$G$2,DLRWISE!B:B,'SUMMARY-M'!B25) -> 45 | O25: =COUNTIFS(DLRWISE!B:B,'SUMMARY-M'!B25,DLRWISE!K:K,"<="&0) -> 7 | P25: =O25/L25 -> 0.14 | Q25: =SUMIF(DLRWISE!B:B,'SUMMARY-M'!B25,DLRWISE!Z:Z) -> 3 | R25: =O25-Q25 -> 4 | S25: =COUNTIFS(DLRWISE!B:B,'SUMMARY-M'!B25,DLRWISE!K:K,0,DLRWISE!N:N,"<"&30) -> 7 | T25: =O25-S25 -> 0
B26: DARANG | C26: SUBHASH ARJEL | D26: SAURABH KUMAR | G26: =IFERROR(F26/E26,0) -> 0 | H26: =COUNTIFS(DLRWISE!S:S,"DEGROWTH",DLRWISE!B:B,'SUMMARY-M'!B26) -> 21 | I26: =H26/L26 -> 0.38888889 | J26: =COUNTIFS(DLRWISE!Y:Y,"DEGROWTH",DLRWISE!B:B,'SUMMARY-M'!B26) -> 25 | K26: =J26/$L26 -> 0.46296296 | L26: =COUNTIFS(DLRWISE!B:B,'SUMMARY-M'!B26) -> 54 | M26: =COUNTIFS(DLRWISE!B:B,'SUMMARY-M'!B26,DLRWISE!H:H,DLRWISE!$H$2) -> 0 | N26: =COUNTIFS(DLRWISE!G:G,DLRWISE!$G$2,DLRWISE!B:B,'SUMMARY-M'!B26) -> 52 | O26: =COUNTIFS(DLRWISE!B:B,'SUMMARY-M'!B26,DLRWISE!K:K,"<="&0) -> 6 | P26: =O26/L26 -> 0.11111111 | Q26: =SUMIF(DLRWISE!B:B,'SUMMARY-M'!B26,DLRWISE!Z:Z) -> 6 | R26: =O26-Q26 -> 0 | S26: =COUNTIFS(DLRWISE!B:B,'SUMMARY-M'!B26,DLRWISE!K:K,0,DLRWISE!N:N,"<"&30) -> 6 | T26: =O26-S26 -> 0
B27: GUWAHATI URBAN | C27: VACANT | D27: SAURABH KUMAR | G27: =IFERROR(F27/E27,0) -> 0 | H27: =COUNTIFS(DLRWISE!S:S,"DEGROWTH",DLRWISE!B:B,'SUMMARY-M'!B27) -> 27 | I27: =H27/L27 -> 0.5 | J27: =COUNTIFS(DLRWISE!Y:Y,"DEGROWTH",DLRWISE!B:B,'SUMMARY-M'!B27) -> 22 | K27: =J27/$L27 -> 0.40740741 | L27: =COUNTIFS(DLRWISE!B:B,'SUMMARY-M'!B27) -> 54 | M27: =COUNTIFS(DLRWISE!B:B,'SUMMARY-M'!B27,DLRWISE!H:H,DLRWISE!$H$2) -> 0 | N27: =COUNTIFS(DLRWISE!G:G,DLRWISE!$G$2,DLRWISE!B:B,'SUMMARY-M'!B27) -> 45 | O27: =COUNTIFS(DLRWISE!B:B,'SUMMARY-M'!B27,DLRWISE!K:K,"<="&0) -> 13 | P27: =O27/L27 -> 0.24074074 | Q27: =SUMIF(DLRWISE!B:B,'SUMMARY-M'!B27,DLRWISE!Z:Z) -> 15 | R27: =O27-Q27 -> -2 | S27: =COUNTIFS(DLRWISE!B:B,'SUMMARY-M'!B27,DLRWISE!K:K,0,DLRWISE!N:N,"<"&30) -> 13 | T27: =O27-S27 -> 0
B28: MORIGAON | C28: VACANT | D28: SAURABH KUMAR | G28: =IFERROR(F28/E28,0) -> 0 | H28: =COUNTIFS(DLRWISE!S:S,"DEGROWTH",DLRWISE!B:B,'SUMMARY-M'!B28) -> 2 | I28: =H28/L28 -> 0.10526316 | J28: =COUNTIFS(DLRWISE!Y:Y,"DEGROWTH",DLRWISE!B:B,'SUMMARY-M'!B28) -> 6 | K28: =J28/$L28 -> 0.31578947 | L28: =COUNTIFS(DLRWISE!B:B,'SUMMARY-M'!B28) -> 19 | M28: =COUNTIFS(DLRWISE!B:B,'SUMMARY-M'!B28,DLRWISE!H:H,DLRWISE!$H$2) -> 0 | N28: =COUNTIFS(DLRWISE!G:G,DLRWISE!$G$2,DLRWISE!B:B,'SUMMARY-M'!B28) -> 19 | O28: =COUNTIFS(DLRWISE!B:B,'SUMMARY-M'!B28,DLRWISE!K:K,"<="&0) -> 1 | P28: =O28/L28 -> 0.052631579 | Q28: =SUMIF(DLRWISE!B:B,'SUMMARY-M'!B28,DLRWISE!Z:Z) -> 0 | R28: =O28-Q28 -> 1 | S28: =COUNTIFS(DLRWISE!B:B,'SUMMARY-M'!B28,DLRWISE!K:K,0,DLRWISE!N:N,"<"&30) -> 1 | T28: =O28-S28 -> 0
B29: Lower Assam- 1 (Bongaigaon) | C29: ANIMESH NATH | D29: SAURABH KUMAR | G29: =IFERROR(F29/E29,0) -> 0 | H29: =COUNTIFS(DLRWISE!S:S,"DEGROWTH",DLRWISE!B:B,'SUMMARY-M'!B29) -> 23 | I29: =H29/L29 -> 0.37704918 | J29: =COUNTIFS(DLRWISE!Y:Y,"DEGROWTH",DLRWISE!B:B,'SUMMARY-M'!B29) -> 31 | K29: =J29/$L29 -> 0.50819672 | L29: =COUNTIFS(DLRWISE!B:B,'SUMMARY-M'!B29) -> 61 | M29: =COUNTIFS(DLRWISE!B:B,'SUMMARY-M'!B29,DLRWISE!H:H,DLRWISE!$H$2) -> 0 | N29: =COUNTIFS(DLRWISE!G:G,DLRWISE!$G$2,DLRWISE!B:B,'SUMMARY-M'!B29) -> 59 | O29: =COUNTIFS(DLRWISE!B:B,'SUMMARY-M'!B29,DLRWISE!K:K,"<="&0) -> 3 | P29: =O29/L29 -> 0.049180328 | Q29: =SUMIF(DLRWISE!B:B,'SUMMARY-M'!B29,DLRWISE!Z:Z) -> 5 | R29: =O29-Q29 -> -2 | S29: =COUNTIFS(DLRWISE!B:B,'SUMMARY-M'!B29,DLRWISE!K:K,0,DLRWISE!N:N,"<"&30) -> 2 | T29: =O29-S29 -> 1
B30: Lower Assam- 2 (Barpeta) | C30: BIKASH KALITA | D30: SAURABH KUMAR | G30: =IFERROR(F30/E30,0) -> 0 | H30: =COUNTIFS(DLRWISE!S:S,"DEGROWTH",DLRWISE!B:B,'SUMMARY-M'!B30) -> 18 | I30: =H30/L30 -> 0.38297872 | J30: =COUNTIFS(DLRWISE!Y:Y,"DEGROWTH",DLRWISE!B:B,'SUMMARY-M'!B30) -> 20 | K30: =J30/$L30 -> 0.42553191 | L30: =COUNTIFS(DLRWISE!B:B,'SUMMARY-M'!B30) -> 47 | M30: =COUNTIFS(DLRWISE!B:B,'SUMMARY-M'!B30,DLRWISE!H:H,DLRWISE!$H$2) -> 0 | N30: =COUNTIFS(DLRWISE!G:G,DLRWISE!$G$2,DLRWISE!B:B,'SUMMARY-M'!B30) -> 45 | O30: =COUNTIFS(DLRWISE!B:B,'SUMMARY-M'!B30,DLRWISE!K:K,"<="&0) -> 7 | P30: =O30/L30 -> 0.14893617 | Q30: =SUMIF(DLRWISE!B:B,'SUMMARY-M'!B30,DLRWISE!Z:Z) -> 6 | R30: =O30-Q30 -> 1 | S30: =COUNTIFS(DLRWISE!B:B,'SUMMARY-M'!B30,DLRWISE!K:K,0,DLRWISE!N:N,"<"&30) -> 5 | T30: =O30-S30 -> 2
B31: Lower Assam- 3 | C31: VACANT ASM LA 3 | D31: SAURABH KUMAR | G31: =IFERROR(F31/E31,0) -> 0 | H31: =COUNTIFS(DLRWISE!S:S,"DEGROWTH",DLRWISE!B:B,'SUMMARY-M'!B31) -> 23 | I31: =H31/L31 -> 0.62162162 | J31: =COUNTIFS(DLRWISE!Y:Y,"DEGROWTH",DLRWISE!B:B,'SUMMARY-M'!B31) -> 0 | K31: =J31/$L31 -> 0 | L31: =COUNTIFS(DLRWISE!B:B,'SUMMARY-M'!B31) -> 37 | M31: =COUNTIFS(DLRWISE!B:B,'SUMMARY-M'!B31,DLRWISE!H:H,DLRWISE!$H$2) -> 0 | N31: =COUNTIFS(DLRWISE!G:G,DLRWISE!$G$2,DLRWISE!B:B,'SUMMARY-M'!B31) -> 36 | O31: =COUNTIFS(DLRWISE!B:B,'SUMMARY-M'!B31,DLRWISE!K:K,"<="&0) -> 6 | P31: =O31/L31 -> 0.16216216 | Q31: =SUMIF(DLRWISE!B:B,'SUMMARY-M'!B31,DLRWISE!Z:Z) -> 5 | R31: =O31-Q31 -> 1 | S31: =COUNTIFS(DLRWISE!B:B,'SUMMARY-M'!B31,DLRWISE!K:K,0,DLRWISE!N:N,"<"&30) -> 6 | T31: =O31-S31 -> 0
B32: TURA HILLS | C32: SAFIOR RAHMAN | D32: SAURABH KUMAR | G32: =IFERROR(F32/E32,0) -> 0 | H32: =COUNTIFS(DLRWISE!S:S,"DEGROWTH",DLRWISE!B:B,'SUMMARY-M'!B32) -> 12 | I32: =H32/L32 -> 0.44444444 | J32: =COUNTIFS(DLRWISE!Y:Y,"DEGROWTH",DLRWISE!B:B,'SUMMARY-M'!B32) -> 17 | K32: =J32/$L32 -> 0.62962963 | L32: =COUNTIFS(DLRWISE!B:B,'SUMMARY-M'!B32) -> 27 | M32: =COUNTIFS(DLRWISE!B:B,'SUMMARY-M'!B32,DLRWISE!H:H,DLRWISE!$H$2) -> 0 | N32: =COUNTIFS(DLRWISE!G:G,DLRWISE!$G$2,DLRWISE!B:B,'SUMMARY-M'!B32) -> 23 | O32: =COUNTIFS(DLRWISE!B:B,'SUMMARY-M'!B32,DLRWISE!K:K,"<="&0) -> 7 | P32: =O32/L32 -> 0.25925926 | Q32: =SUMIF(DLRWISE!B:B,'SUMMARY-M'!B32,DLRWISE!Z:Z) -> 1 | R32: =O32-Q32 -> 6 | S32: =COUNTIFS(DLRWISE!B:B,'SUMMARY-M'!B32,DLRWISE!K:K,0,DLRWISE!N:N,"<"&30) -> 6 | T32: =O32-S32 -> 1
B33: TURA PLAIN | C33: SAFIOR RAHMAN | D33: SAURABH KUMAR | G33: =IFERROR(F33/E33,0) -> 0 | H33: =COUNTIFS(DLRWISE!S:S,"DEGROWTH",DLRWISE!B:B,'SUMMARY-M'!B33) -> 7 | I33: =H33/L33 -> 0.41176471 | J33: =COUNTIFS(DLRWISE!Y:Y,"DEGROWTH",DLRWISE!B:B,'SUMMARY-M'!B33) -> 10 | K33: =J33/$L33 -> 0.58823529 | L33: =COUNTIFS(DLRWISE!B:B,'SUMMARY-M'!B33) -> 17 | M33: =COUNTIFS(DLRWISE!B:B,'SUMMARY-M'!B33,DLRWISE!H:H,DLRWISE!$H$2) -> 0 | N33: =COUNTIFS(DLRWISE!G:G,DLRWISE!$G$2,DLRWISE!B:B,'SUMMARY-M'!B33) -> 17 | O33: =COUNTIFS(DLRWISE!B:B,'SUMMARY-M'!B33,DLRWISE!K:K,"<="&0) -> 4 | P33: =O33/L33 -> 0.23529412 | Q33: =SUMIF(DLRWISE!B:B,'SUMMARY-M'!B33,DLRWISE!Z:Z) -> 1 | R33: =O33-Q33 -> 3 | S33: =COUNTIFS(DLRWISE!B:B,'SUMMARY-M'!B33,DLRWISE!K:K,0,DLRWISE!N:N,"<"&30) -> 3 | T33: =O33-S33 -> 1
B34: AGARTALA | C34: BIKRAM HALDER | D34: GHALIB AYUBI | G34: =IFERROR(F34/E34,0) -> 0 | H34: =COUNTIFS(DLRWISE!S:S,"DEGROWTH",DLRWISE!B:B,'SUMMARY-M'!B34) -> 32 | I34: =H34/L34 -> 0.54237288 | J34: =COUNTIFS(DLRWISE!Y:Y,"DEGROWTH",DLRWISE!B:B,'SUMMARY-M'!B34) -> 29 | K34: =J34/$L34 -> 0.49152542 | L34: =COUNTIFS(DLRWISE!B:B,'SUMMARY-M'!B34) -> 59 | M34: =COUNTIFS(DLRWISE!B:B,'SUMMARY-M'!B34,DLRWISE!H:H,DLRWISE!$H$2) -> 0 | N34: =COUNTIFS(DLRWISE!G:G,DLRWISE!$G$2,DLRWISE!B:B,'SUMMARY-M'!B34) -> 55 | O34: =COUNTIFS(DLRWISE!B:B,'SUMMARY-M'!B34,DLRWISE!K:K,"<="&0) -> 8 | P34: =O34/L34 -> 0.13559322 | Q34: =SUMIF(DLRWISE!B:B,'SUMMARY-M'!B34,DLRWISE!Z:Z) -> 5 | R34: =O34-Q34 -> 3 | S34: =COUNTIFS(DLRWISE!B:B,'SUMMARY-M'!B34,DLRWISE!K:K,0,DLRWISE!N:N,"<"&30) -> 8 | T34: =O34-S34 -> 0
B35: UDAIPUR | C35: BIKRAM HALDER | D35: GHALIB AYUBI | G35: =IFERROR(F35/E35,0) -> 0 | H35: =COUNTIFS(DLRWISE!S:S,"DEGROWTH",DLRWISE!B:B,'SUMMARY-M'!B35) -> 19 | I35: =H35/L35 -> 0.48717949 | J35: =COUNTIFS(DLRWISE!Y:Y,"DEGROWTH",DLRWISE!B:B,'SUMMARY-M'!B35) -> 19 | K35: =J35/$L35 -> 0.48717949 | L35: =COUNTIFS(DLRWISE!B:B,'SUMMARY-M'!B35) -> 39 | M35: =COUNTIFS(DLRWISE!B:B,'SUMMARY-M'!B35,DLRWISE!H:H,DLRWISE!$H$2) -> 0 | N35: =COUNTIFS(DLRWISE!G:G,DLRWISE!$G$2,DLRWISE!B:B,'SUMMARY-M'!B35) -> 39 | O35: =COUNTIFS(DLRWISE!B:B,'SUMMARY-M'!B35,DLRWISE!K:K,"<="&0) -> 0 | P35: =O35/L35 -> 0 | Q35: =SUMIF(DLRWISE!B:B,'SUMMARY-M'!B35,DLRWISE!Z:Z) -> 6 | R35: =O35-Q35 -> -6 | S35: =COUNTIFS(DLRWISE!B:B,'SUMMARY-M'!B35,DLRWISE!K:K,0,DLRWISE!N:N,"<"&30) -> 0 | T35: =O35-S35 -> 0
B36: DHARMANAGAR | C36: BIKRAM HALDER | D36: GHALIB AYUBI | G36: =IFERROR(F36/E36,0) -> 0 | H36: =COUNTIFS(DLRWISE!S:S,"DEGROWTH",DLRWISE!B:B,'SUMMARY-M'!B36) -> 16 | I36: =H36/L36 -> 0.36363636 | J36: =COUNTIFS(DLRWISE!Y:Y,"DEGROWTH",DLRWISE!B:B,'SUMMARY-M'!B36) -> 25 | K36: =J36/$L36 -> 0.56818182 | L36: =COUNTIFS(DLRWISE!B:B,'SUMMARY-M'!B36) -> 44 | M36: =COUNTIFS(DLRWISE!B:B,'SUMMARY-M'!B36,DLRWISE!H:H,DLRWISE!$H$2) -> 0 | N36: =COUNTIFS(DLRWISE!G:G,DLRWISE!$G$2,DLRWISE!B:B,'SUMMARY-M'!B36) -> 41 | O36: =COUNTIFS(DLRWISE!B:B,'SUMMARY-M'!B36,DLRWISE!K:K,"<="&0) -> 6 | P36: =O36/L36 -> 0.13636364 | Q36: =SUMIF(DLRWISE!B:B,'SUMMARY-M'!B36,DLRWISE!Z:Z) -> 6 | R36: =O36-Q36 -> 0 | S36: =COUNTIFS(DLRWISE!B:B,'SUMMARY-M'!B36,DLRWISE!K:K,0,DLRWISE!N:N,"<"&30) -> 6 | T36: =O36-S36 -> 0
... B40: KARIMGANJ | C40: AJIT KURMI | D40: GHALIB AYUBI | G40: =IFERROR(F40/E40,0) -> 0 | H40: =COUNTIFS(DLRWISE!S:S,"DEGROWTH",DLRWISE!B:B,'SUMMARY-M'!B40) -> 9 | I40: =H40/L40 -> 0.3 | J40: =COUNTIFS(DLRWISE!Y:Y,"DEGROWTH",DLRWISE!B:B,'SUMMARY-M'!B40) -> 13 | K40: =J40/$L40 -> 0.43333333 | L40: =COUNTIFS(DLRWISE!B:B,'SUMMARY-M'!B40) -> 30 | M40: =COUNTIFS(DLRWISE!B:B,'SUMMARY-M'!B40,DLRWISE!H:H,DLRWISE!$H$2) -> 0 | N40: =COUNTIFS(DLRWISE!G:G,DLRWISE!$G$2,DLRWISE!B:B,'SUMMARY-M'!B40) -> 29 | O40: =COUNTIFS(DLRWISE!B:B,'SUMMARY-M'!B40,DLRWISE!K:K,"<="&0) -> 6 | P40: =O40/L40 -> 0.2 | Q40: =SUMIF(DLRWISE!B:B,'SUMMARY-M'!B40,DLRWISE!Z:Z) -> 2 | R40: =O40-Q40 -> 4 | S40: =COUNTIFS(DLRWISE!B:B,'SUMMARY-M'!B40,DLRWISE!K:K,0,DLRWISE!N:N,"<"&30) -> 5 | T40: =O40-S40 -> 1
B41: NE 2 TOTAL | E41: =SUM(E25:E40) -> 0 | F41: =SUM(F25:F40) -> 0 | G41: =F41/E41 -> #DIV/0! | H41: =SUM(H25:H40) -> 279 | I41: =H41/L41 -> 0.42465753 | J41: =SUM(J25:J40) -> 294 | K41: =J41/$L41 -> 0.44748858 | L41: =SUM(L25:L40) -> 657 | M41: =SUM(M25:M40) -> 0 | N41: =SUM(N25:N40) -> 608 | O41: =SUM(O25:O40) -> 90 | P41: =O41/L41 -> 0.1369863 | Q41: =SUM(Q25:Q40) -> 76 | R41: =O41-Q41 -> 14 | S41: =SUM(S25:S40) -> 83 | T41: =O41-S41 -> 7
B42: NE TOTAL | E42: =E41+E24 -> 0 | F42: =F41+F24 -> 0 | G42: =F42/E42 -> #DIV/0! | H42: =H41+H24 -> 527 | I42: =H42/L42 -> 0.41627172 | J42: =J41+J24 -> 553 | K42: =J42/$L42 -> 0.43680885 | L42: =L41+L24 -> 1266 | M42: =M41+M24 -> 0 | N42: =N41+N24 -> 1173 | O42: =O41+O24 -> 190 | P42: =O42/L42 -> 0.15007899 | Q42: =Q41+Q24 -> 139 | R42: =O42-Q42 -> 51 | S42: =S41+S24 -> 157 | T42: =O42-S42 -> 33
B43: COOCH BEHAR | C43: VACANT ASM COOCH BEHAR | D43: RITICK CHATTERJEE | G43: =IFERROR(F43/E43,0) -> 0 | H43: =COUNTIFS(DLRWISE!S:S,"DEGROWTH",DLRWISE!B:B,'SUMMARY-M'!B43) -> 13 | I43: =H43/L43 -> 0.36111111 | J43: =COUNTIFS(DLRWISE!Y:Y,"DEGROWTH",DLRWISE!B:B,'SUMMARY-M'!B43) -> 25 | K43: =J43/$L43 -> 0.69444444 | L43: =COUNTIFS(DLRWISE!B:B,'SUMMARY-M'!B43) -> 36 | M43: =COUNTIFS(DLRWISE!B:B,'SUMMARY-M'!B43,DLRWISE!H:H,DLRWISE!$H$2) -> 0 | N43: =COUNTIFS(DLRWISE!G:G,DLRWISE!$G$2,DLRWISE!B:B,'SUMMARY-M'!B43) -> 33 | O43: =COUNTIFS(DLRWISE!B:B,'SUMMARY-M'!B43,DLRWISE!K:K,"<="&0) -> 2 | P43: =O43/L43 -> 0.055555556 | Q43: =SUMIF(DLRWISE!B:B,'SUMMARY-M'!B43,DLRWISE!Z:Z) -> 3 | R43: =O43-Q43 -> -1 | S43: =COUNTIFS(DLRWISE!B:B,'SUMMARY-M'!B43,DLRWISE!K:K,0,DLRWISE!N:N,"<"&30) -> 2 | T43: =O43-S43 -> 0
B44: ALIPURDUAR | C44: ABHIJIT DAM | D44: RITICK CHATTERJEE | G44: =IFERROR(F44/E44,0) -> 0 | H44: =COUNTIFS(DLRWISE!S:S,"DEGROWTH",DLRWISE!B:B,'SUMMARY-M'!B44) -> 6 | I44: =H44/L44 -> 0.35294118 | J44: =COUNTIFS(DLRWISE!Y:Y,"DEGROWTH",DLRWISE!B:B,'SUMMARY-M'!B44) -> 6 | K44: =J44/$L44 -> 0.35294118 | L44: =COUNTIFS(DLRWISE!B:B,'SUMMARY-M'!B44) -> 17 | M44: =COUNTIFS(DLRWISE!B:B,'SUMMARY-M'!B44,DLRWISE!H:H,DLRWISE!$H$2) -> 0 | N44: =COUNTIFS(DLRWISE!G:G,DLRWISE!$G$2,DLRWISE!B:B,'SUMMARY-M'!B44) -> 15 | O44: =COUNTIFS(DLRWISE!B:B,'SUMMARY-M'!B44,DLRWISE!K:K,"<="&0) -> 2 | P44: =O44/L44 -> 0.11764706 | Q44: =SUMIF(DLRWISE!B:B,'SUMMARY-M'!B44,DLRWISE!Z:Z) -> 0 | R44: =O44-Q44 -> 2 | S44: =COUNTIFS(DLRWISE!B:B,'SUMMARY-M'!B44,DLRWISE!K:K,0,DLRWISE!N:N,"<"&30) -> 2 | T44: =O44-S44 -> 0
B45: JALPAIGURI | C45: SHYAMAL CHAKRABORTY | D45: RITICK CHATTERJEE | G45: =IFERROR(F45/E45,0) -> 0 | H45: =COUNTIFS(DLRWISE!S:S,"DEGROWTH",DLRWISE!B:B,'SUMMARY-M'!B45) -> 21 | I45: =H45/L45 -> 0.46666667 | J45: =COUNTIFS(DLRWISE!Y:Y,"DEGROWTH",DLRWISE!B:B,'SUMMARY-M'!B45) -> 29 | K45: =J45/$L45 -> 0.64444444 | L45: =COUNTIFS(DLRWISE!B:B,'SUMMARY-M'!B45) -> 45 | M45: =COUNTIFS(DLRWISE!B:B,'SUMMARY-M'!B45,DLRWISE!H:H,DLRWISE!$H$2) -> 0 | N45: =COUNTIFS(DLRWISE!G:G,DLRWISE!$G$2,DLRWISE!B:B,'SUMMARY-M'!B45) -> 41 | O45: =COUNTIFS(DLRWISE!B:B,'SUMMARY-M'!B45,DLRWISE!K:K,"<="&0) -> 6 | P45: =O45/L45 -> 0.13333333 | Q45: =SUMIF(DLRWISE!B:B,'SUMMARY-M'!B45,DLRWISE!Z:Z) -> 8 | R45: =O45-Q45 -> -2 | S45: =COUNTIFS(DLRWISE!B:B,'SUMMARY-M'!B45,DLRWISE!K:K,0,DLRWISE!N:N,"<"&30) -> 5 | T45: =O45-S45 -> 1
B46: DARJEELING HILLS | C46: ARINDAM SAMADAR | D46: RITICK CHATTERJEE | G46: =IFERROR(F46/E46,0) -> 0 | H46: =COUNTIFS(DLRWISE!S:S,"DEGROWTH",DLRWISE!B:B,'SUMMARY-M'!B46) -> 7 | I46: =H46/L46 -> 0.46666667 | J46: =COUNTIFS(DLRWISE!Y:Y,"DEGROWTH",DLRWISE!B:B,'SUMMARY-M'!B46) -> 5 | K46: =J46/$L46 -> 0.33333333 | L46: =COUNTIFS(DLRWISE!B:B,'SUMMARY-M'!B46) -> 15 | M46: =COUNTIFS(DLRWISE!B:B,'SUMMARY-M'!B46,DLRWISE!H:H,DLRWISE!$H$2) -> 0 | N46: =COUNTIFS(DLRWISE!G:G,DLRWISE!$G$2,DLRWISE!B:B,'SUMMARY-M'!B46) -> 15 | O46: =COUNTIFS(DLRWISE!B:B,'SUMMARY-M'!B46,DLRWISE!K:K,"<="&0) -> 1 | P46: =O46/L46 -> 0.066666667 | Q46: =SUMIF(DLRWISE!B:B,'SUMMARY-M'!B46,DLRWISE!Z:Z) -> 0 | R46: =O46-Q46 -> 1 | S46: =COUNTIFS(DLRWISE!B:B,'SUMMARY-M'!B46,DLRWISE!K:K,0,DLRWISE!N:N,"<"&30) -> 0 | T46: =O46-S46 -> 1
B47: DARJEELING PLAINS | C47: ARINDAM SAMADAR | D47: RITICK CHATTERJEE | G47: =IFERROR(F47/E47,0) -> 0 | H47: =COUNTIFS(DLRWISE!S:S,"DEGROWTH",DLRWISE!B:B,'SUMMARY-M'!B47) -> 4 | I47: =H47/L47 -> 0.36363636 | J47: =COUNTIFS(DLRWISE!Y:Y,"DEGROWTH",DLRWISE!B:B,'SUMMARY-M'!B47) -> 3 | K47: =J47/$L47 -> 0.27272727 | L47: =COUNTIFS(DLRWISE!B:B,'SUMMARY-M'!B47) -> 11 | M47: =COUNTIFS(DLRWISE!B:B,'SUMMARY-M'!B47,DLRWISE!H:H,DLRWISE!$H$2) -> 0 | N47: =COUNTIFS(DLRWISE!G:G,DLRWISE!$G$2,DLRWISE!B:B,'SUMMARY-M'!B47) -> 11 | O47: =COUNTIFS(DLRWISE!B:B,'SUMMARY-M'!B47,DLRWISE!K:K,"<="&0) -> 0 | P47: =O47/L47 -> 0 | Q47: =SUMIF(DLRWISE!B:B,'SUMMARY-M'!B47,DLRWISE!Z:Z) -> 1 | R47: =O47-Q47 -> -1 | S47: =COUNTIFS(DLRWISE!B:B,'SUMMARY-M'!B47,DLRWISE!K:K,0,DLRWISE!N:N,"<"&30) -> 0 | T47: =O47-S47 -> 0
...

Sheet Sheet1
A3: Row Labels | B3: Count of REGION
A4: NE 1 | B4: 448
A5: NE 2 | B5: 541
A6: BH | B6: 151
A7: NB 1 | B7: 120
A8: NB 2 | B8: 65
A9: Grand Total | B9: 1325

Sheet Sheet3
A3: Row Labels
A4: BH
A5: NE 1
A6: NE 2
A7: NB 1
A8: NB 2
A9: Grand Total

Sheet Sheet5
A3: Row Labels | B3: Count of DEALERS NAME
A4: BH | B4: 162
A5: NE 1 | B5: 477
A6: NE 2 | B6: 556
A7: NB 1 | B7: 124
A8: NB 2 | B8: 66
A9: Grand Total | B9: 1385

Sheet Sheet8
A3: Count of REGION
A4: REGION | B4: AREA | C4: Total
A5: BH | B5: BEGUSARAI | C5: 24
A6: BH | B6: BHAGALPUR | C6: 21
A7: BH | B7: KATIHAR | C7: 21
A8: BH | B8: KISHANGANJ | C8: 40
A9: BH | B9: MUZAFFARPUR | C9: 26
A10: BH | B10: PURNIA | C10: 20
A11: BH | B11: SAHARSA | C11: 12
A12: BH | B12: Supaul & Madhepura | C12: 9
A13: NB 1 | B13: ALIPURDUAR | C13: 16
A14: NB 1 | B14: Cooch Behar | C14: 34
A15: NB 1 | B15: DARJEELING HILLS | C15: 16
A16: NB 1 | B16: DARJEELING PLAINS | C16: 12
... A57: NE 2 | B57: UDAIPUR | C57: 39
A58: Grand Total | C58: 1545

Sheet Sheet9
B3: Row Labels | C3: Count of REGION | D3: Sum of asad | F3: Row Labels | G3: Count of REGION
B4: NE 1 | C4: 85 | D4: 0 | F4: NE 1 | G4: 543
B5: NE 2 | C5: 57 | D5: 0 | F5: NE 2 | G5: 615
B6: NB 1 | C6: 18 | D6: 0 | F6: NB 1 | G6: 138
B7: NB 2 | C7: 18 | D7: 0 | F7: NB 2 | G7: 76
B8: BH | C8: 56 | D8: 0 | F8: BH | G8: 173
B9: Grand Total | C9: 234 | D9: 0 | F9: Grand Total | G9: 1545

Sheet DLRWISE (4)
E1: 0 | F1: =TODAY()-5 -> 46305 | G1: 28 | H1: =SUBTOTAL(9,H3:H241) -> 0
A2: REGION | B2: AREA | C2: CODE | D2: SAP | E2: DEALERS NAME | F2: DOA | G2: Prorata Tgt | H2: 46081 | I2: ZERO | J2: REGION | K2: REGION | L2: asad
A3: NE 1 | B3: HOJAI | C3: S019 | D3: 1000000671 | E3: SANDHYA HARDWARE STORES | F3: 38390 | G3: =#REF!/$G$1*($G$1-$E$1) -> #REF! | H3: 0 | I3: 0 | K3: NE 1 | L3: 0
A4: NE 1 | B4: KARBIANGLONG | C4: NEU018 | D4: 1000000675 | E4: UNITED HARDWARE (MANJA) | F4: 42842 | G4: =#REF!/$G$1*($G$1-$E$1) -> #REF! | H4: 0 | I4: 0 | K4: NE 1 | L4: 0
A5: NE 1 | B5: NAGAON | C5: NEM194 | D5: 1000000659 | E5: MUSTAKIM HARDWARE | F5: 43258 | G5: =#REF!/$G$1*($G$1-$E$1) -> #REF! | H5: 0 | I5: 0 | K5: NE 1 | L5: 0
A6: NE 1 | B6: KARBIANGLONG | C6: NER243 | D6: 1000002728 | E6: RAJESH HARDWARE SHOP-HOJAI | F6: 44671 | G6: =#REF!/$G$1*($G$1-$E$1) -> #REF! | H6: 0 | I6: 0 | K6: NE 1 | L6: 0
A7: NE 1 | B7: HOJAI | C7: NEA371 | D7: 1000003243 | E7: ASHOK KEJARIWAL | F7: 44937 | G7: =#REF!/$G$1*($G$1-$E$1) -> #REF! | H7: 0 | I7: 0 | K7: NE 1 | L7: 0
A8: NE 1 | B8: HOJAI | C8: NEH150 | D8: 1000003823 | E8: HILLS HARDWARE & GLASS | F8: 45310 | G8: =#REF!/$G$1*($G$1-$E$1) -> #REF! | H8: 0 | I8: 0 | K8: NE 1 | L8: 0
A9: NE 1 | B9: HOJAI | C9: NEM428 | D9: 1000003948 | E9: MMR HARDWARE STORE | F9: 45422 | G9: =#REF!/$G$1*($G$1-$E$1) -> #REF! | H9: 0 | I9: 0 | K9: NE 1 | L9: 0
A10: NE 1 | B10: LAKHIMPUR | C10: NEB051 | D10: 1000000447 | E10: BALAJI STORE (LAKHIMPUR) | F10: 42510 | G10: =#REF!/$G$1*($G$1-$E$1) -> #REF! | H10: 0 | I10: 0 | K10: NE 1 | L10: 0
A11: NE 1 | B11: LAKHIMPUR | C11: NES674 | D11: 1000003643 | E11: JALAN STEEL | F11: 45126 | G11: =#REF!/$G$1*($G$1-$E$1) -> #REF! | H11: 0 | I11: 1 | K11: NE 1 | L11: 0
A12: NE 1 | B12: DHEMAJI | C12: NEN32 | D12: 1000003971 | E12: NEW MINA HARDWARE | F12: 45439 | G12: =#REF!/$G$1*($G$1-$E$1) -> #REF! | H12: 0 | I12: 0 | K12: NE 1 | L12: 0
A13: NE 1 | B13: AP- Banderdewa | C13: NEM172 | D13: 1000000074 | E13: MEGHA TRADE CENTRE | F13: 43171 | G13: =#REF!/$G$1*($G$1-$E$1) -> #REF! | H13: 0 | I13: 0 | K13: NE 1 | L13: 0
A14: NE 1 | B14: AP- Banderdewa | C14: NEM215 | D14: 1000000072 | E14: MAHESH TRADERS (AP) | F14: 43410 | G14: =#REF!/$G$1*($G$1-$E$1) -> #REF! | H14: 0 | I14: 0 | K14: NE 1 | L14: 0
... A164: NE 2 | B164: MIZORAM | C164: NEH138 | D164: 1000003442 | E164: HS ENTERPRISE | F164: 45008 | G164: =#REF!/$G$1*($G$1-$E$1) -> #REF! | H164: 0 | I164: 1 | K164: NE 2 | L164: 0
A165: NB 2 | B165: UTTAR DINAJPUR | C165: WBS345 | D165: 1000003824 | E165: SAHA & SONS - DALKHOLA | F165: 19.01.2024 | G165: =#REF!/$G$1*($G$1-$E$1) -> #REF! | H165: 0 | I165: 1 | K165: NB 2 | L165: 0
A166: NE 1 | B166: LAKHIMPUR | C166: NER351 | D166: 1000004285 | E166: R.D. ENTERPRISE | F166: 45736 | G166: =#REF!/$G$1*($G$1-$E$1) -> #REF! | H166: 0 | I166: 0 | K166: NE 1 | L166: 0
A167: NE 1 | B167: TINSUKIA | C167: NED263 | D167: 1000004293 | E167: DADAN PRASAD | F167: 45737 | G167: =#REF!/$G$1*($G$1-$E$1) -> #REF! | H167: 0 | I167: 0 | K167: NE 1 | L167: 0
A168: BH | B168: BEGUSARAI | C168: BHS262 | D168: 1000004271 | E168: SANJAY TRADERS - BELDOUR | F168: 45716 | G168: =#REF!/$G$1*($G$1-$E$1) -> #REF! | H168: 0 | I168: 0 | K168: BH | L168: 0
A169: BH | B169: SAHARSA | C169: BHS264 | D169: 1000004303 | E169: SARASWATI TRADERS | F169: 45741 | G169: =#REF!/$G$1*($G$1-$E$1) -> #REF! | H169: 0 | I169: 1 | K169: BH | L169: 0
A170: NB 2 | B170: DAKSHIN DINAJPUR | C170: WBS349 | D170: 1000004319 | E170: SARKAR TRADERS | F170: 44670 | G170: =#REF!/$G$1*($G$1-$E$1) -> #REF! | H170: 0 | I170: 1 | K170: NB 2 | L170: 0
A171: BH | B171: KATIHAR | C171: BHM125 | D171: 1000001982 | E171: MAA TRADING | F171: 44739 | G171: =#REF!/$G$1*($G$1-$E$1) -> #REF! | H171: 0 | I171: 0 | K171: BH | L171: 0
A172: NB 2 | B172: UTTAR DINAJPUR | C172: WBS350 | D172: 1000004320 | E172: S R ENTERPRISE | F172: 45768 | G172: =#REF!/$G$1*($G$1-$E$1) -> #REF! | H172: 0 | I172: 1 | K172: NB 2 | L172: 0
A173: NB 2 | B173: DAKSHIN DINAJPUR | C173: WBL041 | D173: 1000004332 | E173: LAHA ENTERPRISE - TAPAN | F173: 45772 | G173: =#REF!/$G$1*($G$1-$E$1) -> #REF! | H173: 0 | I173: 0 | K173: NB 2 | L173: 0
A174: NE 1 | B174: GOLAGHAT | C174: NEM471 | D174: 1000004336 | E174: MS BADANTA HAZARIKA | F174: 45776 | G174: =#REF!/$G$1*($G$1-$E$1) -> #REF! | H174: 0 | I174: 0 | K174: NE 1 | L174: 0
A175: NE 1 | B175: DHEMAJI | C175: NEK150 | D175: 1000000923 | E175: KAKA BHATIJA BHANDAR . NLP | F175: 44180 | G175: =#REF!/$G$1*($G$1-$E$1) -> #REF! | H175: 0 | I175: 0 | K175: NE 1 | L175: 0
A176: NE 1 | B176: NAGALAND | C176: NEG199 | D176: 1000004283 | E176: GEE BEE ENTERPRISE | F176: 45735 | G176: =#REF!/$G$1*($G$1-$E$1) -> #REF! | H176: 0 | I176: 0 | K176: NE 1 | L176: 0
A177: NB 2 | B177: MALDA | C177: WBM321 | D177: 1000004360 | E177: MASUD HARDWARE | F177: 45798 | G177: =#REF!/$G$1*($G$1-$E$1) -> #REF! | H177: 0 | I177: 0 | K177: NB 2 | L177: 0
... A198: NE 1 | B198: AP- Lekhabali | C198: NEN178 | D198: 1000000105 | E198: NEFA ENTERPRISES | F198: 44738 | G198: =#REF!/$G$1*($G$1-$E$1) -> #REF! | H198: 0 | I198: 0 | K198: NE 1 | L198: 0
A199: NE 1 | B199: AP- Lekhabali | C199: NET212 | D199: 1000004470 | E199: TADUK ENTERPRISES | F199: 45916 | G199: =#REF!/$G$1*($G$1-$E$1) -> #REF! | H199: 0 | K199: NE 1 | L199: 0
A200: BH | B200: BEGUSARAI | C200: BHP040 | D200: 1000002521 | E200: PRABHAT ENTERPRISES | F200: 44739 | G200: =#REF!/$G$1*($G$1-$E$1) -> #REF! | H200: 0 | K200: BH | L200: 0
A201: BH | B201: PURNIA | C201: BHJ062 | D201: 1000004461 | E201: JAY MAA KAMAKHYA ENTERPRISES | F201: 45920 | G201: =#REF!/$G$1*($G$1-$E$1) -> #REF! | H201: 0 | K201: BH | L201: 0
A202: NE 2 | B202: TURA HILLS | C202: NEN251 | D202: 1000004469 | E202: NAMBAT R MARAK | F202: 45915 | G202: =#REF!/$G$1*($G$1-$E$1) -> #REF! | H202: 0 | K202: NE 2 | L202: 0
A203: BH | B203: BEGUSARAI | C203: BHN035 | D203: 1000001984 | E203: NIKITA ENTERPRISES | F203: 44739 | G203: =#REF!/$G$1*($G$1-$E$1) -> #REF! | H203: 0 | K203: BH | L203: 0
A204: BH | B204: KISHANGANJ | C204: BHS270 | D204: 1000004499 | E204: SANAYA ENTERPRISES | F204: 45947 | G204: =#REF!/$G$1*($G$1-$E$1) -> #REF! | H204: 0 | K204: BH | L204: 0
A205: BH | B205: MUZAFFARPUR | C205: BHA103 | D205: 1000004286 | E205: ADITYA TRADERS - DEORIA | F205: 45737 | G205: =#REF!/$G$1*($G$1-$E$1) -> #REF! | H205: 0 | K205: BH | L205: 0
A206: NB 1 | B206: Cooch Behar | C206: S345 | D206: 1000001235 | E206: S.S.CONSTRUCTION | F206: 44739 | G206: =#REF!/$G$1*($G$1-$E$1) -> #REF! | H206: 0 | K206: NB 1 | L206: 0
A207: NE 1 | B207: GOLAGHAT | C207: NER233 | D207: 1000000840 | E207: R.P. STEEL . GOL | F207: 44738 | G207: =#REF!/$G$1*($G$1-$E$1) -> #REF! | H207: 0 | K207: NE 1 | L207: 0
A208: NE 1 | B208: HOJAI | C208: NEN255 | D208: 1000004495 | E208: M/S NOUFA HARDWARE | F208: 45936 | G208: =#REF!/$G$1*($G$1-$E$1) -> #REF! | H208: 0 | K208: NE 1 | L208: 0
A209: NE 1 | B209: JORHAT | C209: NEF045 | D209: 1000004500 | E209: M.S. ENTERPRISE | F209: 45948 | G209: =#REF!/$G$1*($G$1-$E$1) -> #REF! | H209: 0 | K209: NE 1 | L209: 0
...

Sheet DLRWISE (5)
E1: 2 | F1: =TODAY()-5 -> 46305 | I1: 46112 | J1: 30 | K1: =SUBTOTAL(9,K3:K1790) -> 375595.15 | N1: =SUBTOTAL(9,N3:N1661) -> 404486.5 | P1: =SUBTOTAL(9,P3:P1790) -> 406376.5 | T1: =SUBTOTAL(9,T3:T1661) -> 313779 | V1: =SUBTOTAL(9,V3:V1790) -> 314266.75
A2: REGION | B2: AREA | C2: CODE | D2: SAP | E2: DEALERS NAME | F2: DOA | G2: Targeted Dealer | H2: EXCLUSIVE DEALER | I2: Apr'26 Tgt | J2: Prorata Tgt | K2: 46142 | L2: Shortfall | M2: Prorata Achv % | N2: Mar'26 SALE | O2: Mar'26 DEALER | P2: Mar'26 SALE | Q2: VARIENCE | R2: GROWTH % | S2: Apr-26 Vs Mar-26 | T2: Apr-25 SALE | U2: Apr-25 Dealer | V2: Apr-25 SALE | W2: LYSM VARIENCE | X2: LYSM GROWTH % | Y2: Apr-25 SALE | Z2: ZERO | AA2: REGION | AB2: REGION | AC2: REGION | AD2: SD
A3: NE 1 | B3: NAGAON | C3: B014 | D3: 1000000638 | E3: BANIK HARDWARE | F3: 38384 | G3: =IF(I3>0,"Targeted Dealer","-") -> Targeted Dealer | I3: 100 | J3: =I3/$J$1*($J$1-$E$1) -> 93.333333 | K3: 60 | L3: =I3-K3 -> 40 | M3: =IFERROR((K3/J3%),"-") -> 64.285714 | N3: 222 | O3: =IF(F3<=$P$2,"Mar","") -> Mar | P3: =N3 -> 222 | Q3: =K3-P3 -> -162 | R3: =IFERROR(IF(O3="Mar",(K3/P3-1))," ") -> -0.72972973 | S3: =IF(N3>0,IF(O3="","-",IF(R3<0%,"DEGROWTH","GROWTH"))) -> DEGROWTH | T3: 60 | U3: =IF(F3<=$V$2,"Apr","") -> Apr | V3: 60 | W3: =K3-V3 -> 0 | X3: =IFERROR(IF(U3="Apr",(K3/V3-1)),0) -> 0 | Y3: =IF(T3>0,IF(U3="","-",IF(X3<0%,"DEGROWTH","GROWTH"))) -> GROWTH | Z3: 0 | AB3: NE 1 | AC3: NE 1 | AD3: =IF(K3=0,1,0) -> 0
A4: NE 1 | B4: HOJAI | C4: S019 | D4: 1000000671 | E4: SANDHYA HARDWARE STORES | F4: 38390 | G4: =IF(I4>0,"Targeted Dealer","-") -> Targeted Dealer | I4: 10 | J4: =I4/$J$1*($J$1-$E$1) -> 9.3333333 | K4: 0 | L4: =I4-K4 -> 10 | M4: =IFERROR((K4/J4%),"-") -> 0 | N4: 0 | O4: =IF(F4<=$P$2,"Mar","") -> Mar | P4: =N4 -> 0 | Q4: =K4-P4 -> 0 | R4: =IFERROR(IF(O4="Mar",(K4/P4-1))," ") | S4: =IF(N4>0,IF(O4="","-",IF(R4<0%,"DEGROWTH","GROWTH"))) -> FALSE | T4: 20 | U4: =IF(F4<=$V$2,"Apr","") -> Apr | V4: 20 | W4: =K4-V4 -> -20 | X4: =IFERROR(IF(U4="Apr",(K4/V4-1)),0) -> -1 | Y4: =IF(T4>0,IF(U4="","-",IF(X4<0%,"DEGROWTH","GROWTH"))) -> DEGROWTH | Z4: 0 | AB4: NE 1 | AC4: NE 1 | AD4: =IF(K4=0,1,0) -> 1
A5: NE 1 | B5: HOJAI | C5: S078 | D5: 1000000673 | E5: SREE BHANDER (SP FIRM) | F5: 38490 | G5: =IF(I5>0,"Targeted Dealer","-") -> Targeted Dealer | I5: 2060 | J5: =I5/$J$1*($J$1-$E$1) -> 1922.6667 | K5: 1680 | L5: =I5-K5 -> 380 | M5: =IFERROR((K5/J5%),"-") -> 87.378641 | N5: 1609 | O5: =IF(F5<=$P$2,"Mar","") -> Mar | P5: =N5 -> 1609 | Q5: =K5-P5 -> 71 | R5: =IFERROR(IF(O5="Mar",(K5/P5-1))," ") -> 0.044126787 | S5: =IF(N5>0,IF(O5="","-",IF(R5<0%,"DEGROWTH","GROWTH"))) -> GROWTH | T5: 1869.5 | U5: =IF(F5<=$V$2,"Apr","") -> Apr | V5: 1869.5 | W5: =K5-V5 -> -189.5 | X5: =IFERROR(IF(U5="Apr",(K5/V5-1)),0) -> -0.101364 | Y5: =IF(T5>0,IF(U5="","-",IF(X5<0%,"DEGROWTH","GROWTH"))) -> DEGROWTH | Z5: 0 | AB5: NE 1 | AC5: NE 1 | AD5: =IF(K5=0,1,0) -> 0
A6: NE 1 | B6: NAGAON | C6: S012 | D6: 1000000669 | E6: SAIKIA ENTERPRISE | F6: 39093 | G6: =IF(I6>0,"Targeted Dealer","-") -> Targeted Dealer | I6: 40 | J6: =I6/$J$1*($J$1-$E$1) -> 37.333333 | K6: 39 | L6: =I6-K6 -> 1 | M6: =IFERROR((K6/J6%),"-") -> 104.46429 | N6: 26 | O6: =IF(F6<=$P$2,"Mar","") -> Mar | P6: =N6 -> 26 | Q6: =K6-P6 -> 13 | R6: =IFERROR(IF(O6="Mar",(K6/P6-1))," ") -> 0.5 | S6: =IF(N6>0,IF(O6="","-",IF(R6<0%,"DEGROWTH","GROWTH"))) -> GROWTH | T6: 0 | U6: =IF(F6<=$V$2,"Apr","") -> Apr | V6: 0 | W6: =K6-V6 -> 39 | X6: =IFERROR(IF(U6="Apr",(K6/V6-1)),0) -> 0 | Y6: =IF(T6>0,IF(U6="","-",IF(X6<0%,"DEGROWTH","GROWTH"))) -> FALSE | Z6: 0 | AB6: NE 1 | AC6: NE 1 | AD6: =IF(K6=0,1,0) -> 0
A7: NE 1 | B7: NAGAON | C7: S113 | D7: 1000000668 | E7: S.N.HARDWARE (NAGAON) | F7: 39257 | G7: =IF(I7>0,"Targeted Dealer","-") -> Targeted Dealer | I7: 36 | J7: =I7/$J$1*($J$1-$E$1) -> 33.6 | K7: 13 | L7: =I7-K7 -> 23 | M7: =IFERROR((K7/J7%),"-") -> 38.690476 | N7: 13 | O7: =IF(F7<=$P$2,"Mar","") -> Mar | P7: =N7 -> 13 | Q7: =K7-P7 -> 0 | R7: =IFERROR(IF(O7="Mar",(K7/P7-1))," ") -> 0 | S7: =IF(N7>0,IF(O7="","-",IF(R7<0%,"DEGROWTH","GROWTH"))) -> GROWTH | T7: 13 | U7: =IF(F7<=$V$2,"Apr","") -> Apr | V7: 13 | W7: =K7-V7 -> 0 | X7: =IFERROR(IF(U7="Apr",(K7/V7-1)),0) -> 0 | Y7: =IF(T7>0,IF(U7="","-",IF(X7<0%,"DEGROWTH","GROWTH"))) -> GROWTH | Z7: 0 | AB7: NE 1 | AC7: NE 1 | AD7: =IF(K7=0,1,0) -> 0
A8: NE 1 | B8: HOJAI | C8: R096 | D8: 1000000665 | E8: RAFIK HARDWARE | F8: 40672 | G8: =IF(I8>0,"Targeted Dealer","-") -> Targeted Dealer | I8: 300 | J8: =I8/$J$1*($J$1-$E$1) -> 280 | K8: 380 | L8: =I8-K8 -> -80 | M8: =IFERROR((K8/J8%),"-") -> 135.71429 | N8: 280 | O8: =IF(F8<=$P$2,"Mar","") -> Mar | P8: =N8 -> 280 | Q8: =K8-P8 -> 100 | R8: =IFERROR(IF(O8="Mar",(K8/P8-1))," ") -> 0.35714286 | S8: =IF(N8>0,IF(O8="","-",IF(R8<0%,"DEGROWTH","GROWTH"))) -> GROWTH | T8: 300 | U8: =IF(F8<=$V$2,"Apr","") -> Apr | V8: 300 | W8: =K8-V8 -> 80 | X8: =IFERROR(IF(U8="Apr",(K8/V8-1)),0) -> 0.26666667 | Y8: =IF(T8>0,IF(U8="","-",IF(X8<0%,"DEGROWTH","GROWTH"))) -> GROWTH | Z8: 0 | AB8: NE 1 | AC8: NE 1 | AD8: =IF(K8=0,1,0) -> 0
A9: NE 1 | B9: NAGAON | C9: M238 | D9: 1000000653 | E9: MAA HARDWARE (NAGAON) | F9: 41186 | G9: =IF(I9>0,"Targeted Dealer","-") -> Targeted Dealer | I9: 100 | J9: =I9/$J$1*($J$1-$E$1) -> 93.333333 | K9: 40 | L9: =I9-K9 -> 60 | M9: =IFERROR((K9/J9%),"-") -> 42.857143 | N9: 40 | O9: =IF(F9<=$P$2,"Mar","") -> Mar | P9: =N9 -> 40 | Q9: =K9-P9 -> 0 | R9: =IFERROR(IF(O9="Mar",(K9/P9-1))," ") -> 0 | S9: =IF(N9>0,IF(O9="","-",IF(R9<0%,"DEGROWTH","GROWTH"))) -> GROWTH | T9: 90 | U9: =IF(F9<=$V$2,"Apr","") -> Apr | V9: 90 | W9: =K9-V9 -> -50 | X9: =IFERROR(IF(U9="Apr",(K9/V9-1)),0) -> -0.55555556 | Y9: =IF(T9>0,IF(U9="","-",IF(X9<0%,"DEGROWTH","GROWTH"))) -> DEGROWTH | Z9: 0 | AB9: NE 1 | AC9: NE 1 | AD9: =IF(K9=0,1,0) -> 0
A10: NE 1 | B10: HOJAI | C10: A162 | D10: 1000000634 | E10: ALAM AGRO INDUSTRY | F10: 41397 | G10: =IF(I10>0,"Targeted Dealer","-") -> Targeted Dealer | I10: 136 | J10: =I10/$J$1*($J$1-$E$1) -> 126.93333 | K10: 190 | L10: =I10-K10 -> -54 | M10: =IFERROR((K10/J10%),"-") -> 149.68487 | N10: 140 | O10: =IF(F10<=$P$2,"Mar","") -> Mar | P10: =N10 -> 140 | Q10: =K10-P10 -> 50 | R10: =IFERROR(IF(O10="Mar",(K10/P10-1))," ") -> 0.35714286 | S10: =IF(N10>0,IF(O10="","-",IF(R10<0%,"DEGROWTH","GROWTH"))) -> GROWTH | T10: 100 | U10: =IF(F10<=$V$2,"Apr","") -> Apr | V10: 100 | W10: =K10-V10 -> 90 | X10: =IFERROR(IF(U10="Apr",(K10/V10-1)),0) -> 0.9 | Y10: =IF(T10>0,IF(U10="","-",IF(X10<0%,"DEGROWTH","GROWTH"))) -> GROWTH | Z10: 0 | AB10: NE 1 | AC10: NE 1 | AD10: =IF(K10=0,1,0) -> 0
A11: NE 1 | B11: HOJAI | C11: NEM008 | D11: 1000000654 | E11: MAA MANASA HARDWARE (HOJAI) | F11: 41791 | G11: =IF(I11>0,"Targeted Dealer","-") -> Targeted Dealer | I11: 203 | J11: =I11/$J$1*($J$1-$E$1) -> 189.46667 | K11: 141 | L11: =I11-K11 -> 62 | M11: =IFERROR((K11/J11%),"-") -> 74.419423 | N11: 81 | O11: =IF(F11<=$P$2,"Mar","") -> Mar | P11: =N11 -> 81 | Q11: =K11-P11 -> 60 | R11: =IFERROR(IF(O11="Mar",(K11/P11-1))," ") -> 0.74074074 | S11: =IF(N11>0,IF(O11="","-",IF(R11<0%,"DEGROWTH","GROWTH"))) -> GROWTH | T11: 180 | U11: =IF(F11<=$V$2,"Apr","") -> Apr | V11: 180 | W11: =K11-V11 -> -39 | X11: =IFERROR(IF(U11="Apr",(K11/V11-1)),0) -> -0.21666667 | Y11: =IF(T11>0,IF(U11="","-",IF(X11<0%,"DEGROWTH","GROWTH"))) -> DEGROWTH | Z11: 0 | AB11: NE 1 | AC11: NE 1 | AD11: =IF(K11=0,1,0) -> 0
A12: NE 1 | B12: NAGAON | C12: NEM025 | D12: 1000000655 | E12: MAHABIR HARDWARE (DOOM DOOMIA) | F12: 41927 | G12: =IF(I12>0,"Targeted Dealer","-") -> Targeted Dealer | I12: 41 | J12: =I12/$J$1*($J$1-$E$1) -> 38.266667 | K12: 20 | L12: =I12-K12 -> 21 | M12: =IFERROR((K12/J12%),"-") -> 52.264808 | N12: 20 | O12: =IF(F12<=$P$2,"Mar","") -> Mar | P12: =N12 -> 20 | Q12: =K12-P12 -> 0 | R12: =IFERROR(IF(O12="Mar",(K12/P12-1))," ") -> 0 | S12: =IF(N12>0,IF(O12="","-",IF(R12<0%,"DEGROWTH","GROWTH"))) -> GROWTH | T12: 20 | U12: =IF(F12<=$V$2,"Apr","") -> Apr | V12: 20 | W12: =K12-V12 -> 0 | X12: =IFERROR(IF(U12="Apr",(K12/V12-1)),0) -> 0 | Y12: =IF(T12>0,IF(U12="","-",IF(X12<0%,"DEGROWTH","GROWTH"))) -> GROWTH | Z12: 0 | AB12: NE 1 | AC12: NE 1 | AD12: =IF(K12=0,1,0) -> 0
A13: NE 1 | B13: HOJAI | C13: NEA028 | D13: 1000000633 | E13: A. HAQUE HARDWARE | F13: 42048 | G13: =IF(I13>0,"Targeted Dealer","-") -> Targeted Dealer | I13: 181 | J13: =I13/$J$1*($J$1-$E$1) -> 168.93333 | K13: 153 | L13: =I13-K13 -> 28 | M13: =IFERROR((K13/J13%),"-") -> 90.568272 | N13: 120 | O13: =IF(F13<=$P$2,"Mar","") -> Mar | P13: =N13 -> 120 | Q13: =K13-P13 -> 33 | R13: =IFERROR(IF(O13="Mar",(K13/P13-1))," ") -> 0.275 | S13: =IF(N13>0,IF(O13="","-",IF(R13<0%,"DEGROWTH","GROWTH"))) -> GROWTH | T13: 180 | U13: =IF(F13<=$V$2,"Apr","") -> Apr | V13: 180 | W13: =K13-V13 -> -27 | X13: =IFERROR(IF(U13="Apr",(K13/V13-1)),0) -> -0.15 | Y13: =IF(T13>0,IF(U13="","-",IF(X13<0%,"DEGROWTH","GROWTH"))) -> DEGROWTH | Z13: 0 | AB13: NE 1 | AC13: NE 1 | AD13: =IF(K13=0,1,0) -> 0
A14: NE 1 | B14: HOJAI | C14: NES132 | D14: 1000000672 | E14: SHARMA HARDWARE (NAGAON) | F14: 42448 | G14: =IF(I14>0,"Targeted Dealer","-") -> Targeted Dealer | I14: 70 | J14: =I14/$J$1*($J$1-$E$1) -> 65.333333 | K14: 18 | L14: =I14-K14 -> 52 | M14: =IFERROR((K14/J14%),"-") -> 27.55102 | N14: 46 | O14: =IF(F14<=$P$2,"Mar","") -> Mar | P14: =N14 -> 46 | Q14: =K14-P14 -> -28 | R14: =IFERROR(IF(O14="Mar",(K14/P14-1))," ") -> -0.60869565 | S14: =IF(N14>0,IF(O14="","-",IF(R14<0%,"DEGROWTH","GROWTH"))) -> DEGROWTH | T14: 40 | U14: =IF(F14<=$V$2,"Apr","") -> Apr | V14: 40 | W14: =K14-V14 -> -22 | X14: =IFERROR(IF(U14="Apr",(K14/V14-1)),0) -> -0.55 | Y14: =IF(T14>0,IF(U14="","-",IF(X14<0%,"DEGROWTH","GROWTH"))) -> DEGROWTH | Z14: 0 | AB14: NE 1 | AC14: NE 1 | AD14: =IF(K14=0,1,0) -> 0
... A1319: NE 1 | B1319: MANIPUR | C1319: T053 | D1319: 1000000580 | E1319: THANGJING HARDWARE | F1319: 44738 | G1319: =IF(I1319>0,"Targeted Dealer","-") -> Targeted Dealer | I1319: 55 | J1319: =I1319/$J$1*($J$1-$E$1) -> 51.333333 | K1319: 233 | L1319: =I1319-K1319 -> -178 | M1319: =IFERROR((K1319/J1319%),"-") -> 453.8961 | N1319: 159 | O1319: =IF(F1319<=$P$2,"Mar","") -> Mar | P1319: =N1319 -> 159 | Q1319: =K1319-P1319 -> 74 | R1319: =IFERROR(IF(O1319="Mar",(K1319/P1319-1))," ") -> 0.46540881 | S1319: =IF(N1319>0,IF(O1319="","-",IF(R1319<0%,"DEGROWTH","GROWTH"))) -> GROWTH | T1319: 0 | U1319: =IF(F1319<=$V$2,"Apr","") -> Apr | V1319: 0 | W1319: =K1319-V1319 -> 233 | X1319: =IFERROR(IF(U1319="Apr",(K1319/V1319-1)),0) -> 0 | Y1319: =IF(T1319>0,IF(U1319="","-",IF(X1319<0%,"DEGROWTH","GROWTH"))) -> FALSE | Z1319: 0 | AB1319: NE 1 | AC1319: NE 1 | AD1319: =IF(K1319=0,1,0) -> 0
A1320: NE 1 | B1320: TEZPUR | C1320: NER348 | D1320: 1000004227 | E1320: R M HARDWARE | F1320: 28.01.2025 | G1320: =IF(I1320>0,"Targeted Dealer","-") -> Targeted Dealer | I1320: 70 | J1320: =I1320/$J$1*($J$1-$E$1) -> 65.333333 | K1320: 29.7 | L1320: =I1320-K1320 -> 40.3 | M1320: =IFERROR((K1320/J1320%),"-") -> 45.459184 | N1320: 117.5 | O1320: =IF(F1320<=$P$2,"Mar","") -> Mar | P1320: =N1320 -> 117.5 | Q1320: =K1320-P1320 -> -87.8 | R1320: =IFERROR(IF(O1320="Mar",(K1320/P1320-1))," ") -> -0.74723404 | S1320: =IF(N1320>0,IF(O1320="","-",IF(R1320<0%,"DEGROWTH","GROWTH"))) -> DEGROWTH | T1320: 61.5 | U1320: =IF(F1320<=$V$2,"Apr","") -> Apr | V1320: 61.5 | W1320: =K1320-V1320 -> -31.8 | X1320: =IFERROR(IF(U1320="Apr",(K1320/V1320-1)),0) -> -0.51707317 | Y1320: =IF(T1320>0,IF(U1320="","-",IF(X1320<0%,"DEGROWTH","GROWTH"))) -> DEGROWTH | Z1320: 0 | AB1320: NE 1 | AC1320: NE 1 | AD1320: =IF(K1320=0,1,0) -> 0
A1321: BH | B1321: KATIHAR | C1321: BHS261 | D1321: 1000004242 | E1321: SAGAR KHAD BEEJ BHANDAR | F1321: 45686 | G1321: =IF(I1321>0,"Targeted Dealer","-") -> Targeted Dealer | I1321: 30 | J1321: =I1321/$J$1*($J$1-$E$1) -> 28 | K1321: 25 | L1321: =I1321-K1321 -> 5 | M1321: =IFERROR((K1321/J1321%),"-") -> 89.285714 | N1321: 0 | O1321: =IF(F1321<=$P$2,"Mar","") -> Mar | P1321: =N1321 -> 0 | Q1321: =K1321-P1321 -> 25 | R1321: =IFERROR(IF(O1321="Mar",(K1321/P1321-1))," ") | S1321: =IF(N1321>0,IF(O1321="","-",IF(R1321<0%,"DEGROWTH","GROWTH"))) -> FALSE | T1321: 37 | U1321: =IF(F1321<=$V$2,"Apr","") -> Apr | V1321: 37 | W1321: =K1321-V1321 -> -12 | X1321: =IFERROR(IF(U1321="Apr",(K1321/V1321-1)),0) -> -0.32432432 | Y1321: =IF(T1321>0,IF(U1321="","-",IF(X1321<0%,"DEGROWTH","GROWTH"))) -> DEGROWTH | Z1321: 0 | AB1321: NE 1 | AC1321: BH | AD1321: =IF(K1321=0,1,0) -> 0
A1322: NE 2 | B1322: CACHAR | C1322: NES777 | D1322: 1000004230 | E1322: SUMITA TRADERS | F1322: 45685 | G1322: =IF(I1322>0,"Targeted Dealer","-") -> Targeted Dealer | I1322: 40 | J1322: =I1322/$J$1*($J$1-$E$1) -> 37.333333 | K1322: 15 | L1322: =I1322-K1322 -> 25 | M1322: =IFERROR((K1322/J1322%),"-") -> 40.178571 | N1322: 32 | O1322: =IF(F1322<=$P$2,"Mar","") -> Mar | P1322: =N1322 -> 32 | Q1322: =K1322-P1322 -> -17 | R1322: =IFERROR(IF(O1322="Mar",(K1322/P1322-1))," ") -> -0.53125 | S1322: =IF(N1322>0,IF(O1322="","-",IF(R1322<0%,"DEGROWTH","GROWTH"))) -> DEGROWTH | T1322: 57.5 | U1322: =IF(F1322<=$V$2,"Apr","") -> Apr | V1322: 57.5 | W1322: =K1322-V1322 -> -42.5 | X1322: =IFERROR(IF(U1322="Apr",(K1322/V1322-1)),0) -> -0.73913043 | Y1322: =IF(T1322>0,IF(U1322="","-",IF(X1322<0%,"DEGROWTH","GROWTH"))) -> DEGROWTH | Z1322: 0 | AB1322: NE 1 | AC1322: NE 2 | AD1322: =IF(K1322=0,1,0) -> 0
A1323: NE 2 | B1323: KARIMGANJ | C1323: NEA488 | D1323: 1000004262 | E1323: A & A ENTERPRISE | F1323: 45689 | G1323: =IF(I1323>0,"Targeted Dealer","-") -> Targeted Dealer | I1323: 10 | J1323: =I1323/$J$1*($J$1-$E$1) -> 9.3333333 | K1323: 0 | L1323: =I1323-K1323 -> 10 | M1323: =IFERROR((K1323/J1323%),"-") -> 0 | N1323: 0 | O1323: =IF(F1323<=$P$2,"Mar","") -> Mar | P1323: =N1323 -> 0 | Q1323: =K1323-P1323 -> 0 | R1323: =IFERROR(IF(O1323="Mar",(K1323/P1323-1))," ") | S1323: =IF(N1323>0,IF(O1323="","-",IF(R1323<0%,"DEGROWTH","GROWTH"))) -> FALSE | T1323: 26 | U1323: =IF(F1323<=$V$2,"Apr","") -> Apr | V1323: 26 | W1323: =K1323-V1323 -> -26 | X1323: =IFERROR(IF(U1323="Apr",(K1323/V1323-1)),0) -> -1 | Y1323: =IF(T1323>0,IF(U1323="","-",IF(X1323<0%,"DEGROWTH","GROWTH"))) -> DEGROWTH | Z1323: 0 | AB1323: NE 1 | AC1323: NE 2 | AD1323: =IF(K1323=0,1,0) -> 1
A1324: NE 1 | B1324: MANIPUR | C1324: NEP309 | D1324: 1000004224 | E1324: PK AGENCY | F1324: 45684 | G1324: =IF(I1324>0,"Targeted Dealer","-") -> Targeted Dealer | I1324: 55 | J1324: =I1324/$J$1*($J$1-$E$1) -> 51.333333 | K1324: 0 | L1324: =I1324-K1324 -> 55 | M1324: =IFERROR((K1324/J1324%),"-") -> 0 | N1324: 0 | O1324: =IF(F1324<=$P$2,"Mar","") -> Mar | P1324: =N1324 -> 0 | Q1324: =K1324-P1324 -> 0 | R1324: =IFERROR(IF(O1324="Mar",(K1324/P1324-1))," ") | S1324: =IF(N1324>0,IF(O1324="","-",IF(R1324<0%,"DEGROWTH","GROWTH"))) -> FALSE | T1324: 28 | U1324: =IF(F1324<=$V$2,"Apr","") -> Apr | V1324: 28 | W1324: =K1324-V1324 -> -28 | X1324: =IFERROR(IF(U1324="Apr",(K1324/V1324-1)),0) -> -1 | Y1324: =IF(T1324>0,IF(U1324="","-",IF(X1324<0%,"DEGROWTH","GROWTH"))) -> DEGROWTH | Z1324: 0 | AB1324: NE 1 | AC1324: NE 1 | AD1324: =IF(K1324=0,1,0) -> 1
A1325: NE 2 | B1325: GUWAHATI URBAN | C1325: NEA484 | D1325: 1000004213 | E1325: ANAND HARDWARE | F1325: 45667 | G1325: =IF(I1325>0,"Targeted Dealer","-") -> Targeted Dealer | I1325: 20 | J1325: =I1325/$J$1*($J$1-$E$1) -> 18.666667 | K1325: 0 | L1325: =I1325-K1325 -> 20 | M1325: =IFERROR((K1325/J1325%),"-") -> 0 | N1325: 0 | O1325: =IF(F1325<=$P$2,"Mar","") -> Mar | P1325: =N1325 -> 0 | Q1325: =K1325-P1325 -> 0 | R1325: =IFERROR(IF(O1325="Mar",(K1325/P1325-1))," ") | S1325: =IF(N1325>0,IF(O1325="","-",IF(R1325<0%,"DEGROWTH","GROWTH"))) -> FALSE | T1325: 6 | U1325: =IF(F1325<=$V$2,"Apr","") -> Apr | V1325: 6 | W1325: =K1325-V1325 -> -6 | X1325: =IFERROR(IF(U1325="Apr",(K1325/V1325-1)),0) -> -1 | Y1325: =IF(T1325>0,IF(U1325="","-",IF(X1325<0%,"DEGROWTH","GROWTH"))) -> DEGROWTH | Z1325: 0 | AB1325: NE 1 | AC1325: NE 2 | AD1325: =IF(K1325=0,1,0) -> 1
A1326: NE 1 | B1326: NAGAON | C1326: NES770 | D1326: 1000004186 | E1326: SHRI SIDDHIVINAYAK STEEL | F1326: 45636 | G1326: =IF(I1326>0,"Targeted Dealer","-") -> Targeted Dealer | I1326: 50 | J1326: =I1326/$J$1*($J$1-$E$1) -> 46.666667 | K1326: 13 | L1326: =I1326-K1326 -> 37 | M1326: =IFERROR((K1326/J1326%),"-") -> 27.857143 | N1326: 26 | O1326: =IF(F1326<=$P$2,"Mar","") -> Mar | P1326: =N1326 -> 26 | Q1326: =K1326-P1326 -> -13 | R1326: =IFERROR(IF(O1326="Mar",(K1326/P1326-1))," ") -> -0.5 | S1326: =IF(N1326>0,IF(O1326="","-",IF(R1326<0%,"DEGROWTH","GROWTH"))) -> DEGROWTH | T1326: 62 | U1326: =IF(F1326<=$V$2,"Apr","") -> Apr | V1326: 62 | W1326: =K1326-V1326 -> -49 | X1326: =IFERROR(IF(U1326="Apr",(K1326/V1326-1)),0) -> -0.79032258 | Y1326: =IF(T1326>0,IF(U1326="","-",IF(X1326<0%,"DEGROWTH","GROWTH"))) -> DEGROWTH | Z1326: 0 | AB1326: NE 1 | AC1326: NE 1 | AD1326: =IF(K1326=0,1,0) -> 0
A1327: NE 1 | B1327: AP- Tinsukia Side | C1327: NEH102 | D1327: 1000000116 | E1327: HANNON ENTERPRISE . APS | F1327: 44738 | G1327: =IF(I1327>0,"Targeted Dealer","-") -> Targeted Dealer | I1327: 30 | J1327: =I1327/$J$1*($J$1-$E$1) -> 28 | K1327: 0 | L1327: =I1327-K1327 -> 30 | M1327: =IFERROR((K1327/J1327%),"-") -> 0 | N1327: 30 | O1327: =IF(F1327<=$P$2,"Mar","") -> Mar | P1327: =N1327 -> 30 | Q1327: =K1327-P1327 -> -30 | R1327: =IFERROR(IF(O1327="Mar",(K1327/P1327-1))," ") -> -1 | S1327: =IF(N1327>0,IF(O1327="","-",IF(R1327<0%,"DEGROWTH","GROWTH"))) -> DEGROWTH | T1327: 0 | U1327: =IF(F1327<=$V$2,"Apr","") -> Apr | V1327: 0 | W1327: =K1327-V1327 -> 0 | X1327: =IFERROR(IF(U1327="Apr",(K1327/V1327-1)),0) -> 0 | Y1327: =IF(T1327>0,IF(U1327="","-",IF(X1327<0%,"DEGROWTH","GROWTH"))) -> FALSE | Z1327: 0 | AB1327: NE 1 | AC1327: NE 1 | AD1327: =IF(K1327=0,1,0) -> 1
A1328: NE 1 | B1328: GOLAGHAT | C1328: NES645 | D1328: 1000003453 | E1328: SARMAH SUPPLIERS | F1328: 45012 | G1328: =IF(I1328>0,"Targeted Dealer","-") -> Targeted Dealer | I1328: 30 | J1328: =I1328/$J$1*($J$1-$E$1) -> 28 | K1328: 20 | L1328: =I1328-K1328 -> 10 | M1328: =IFERROR((K1328/J1328%),"-") -> 71.428571 | N1328: 20 | O1328: =IF(F1328<=$P$2,"Mar","") -> Mar | P1328: =N1328 -> 20 | Q1328: =K1328-P1328 -> 0 | R1328: =IFERROR(IF(O1328="Mar",(K1328/P1328-1))," ") -> 0 | S1328: =IF(N1328>0,IF(O1328="","-",IF(R1328<0%,"DEGROWTH","GROWTH"))) -> GROWTH | T1328: 10 | U1328: =IF(F1328<=$V$2,"Apr","") -> Apr | V1328: 10 | W1328: =K1328-V1328 -> 10 | X1328: =IFERROR(IF(U1328="Apr",(K1328/V1328-1)),0) -> 1 | Y1328: =IF(T1328>0,IF(U1328="","-",IF(X1328<0%,"DEGROWTH","GROWTH"))) -> GROWTH | Z1328: 0 | AB1328: NE 1 | AC1328: NE 1 | AD1328: =IF(K1328=0,1,0) -> 0
A1329: NE 1 | B1329: SIBSAGAR | C1329: NED228 | D1329: 1000003588 | E1329: DEEPLING HARDWARE STORE | F1329: 45084 | G1329: =IF(I1329>0,"Targeted Dealer","-") -> Targeted Dealer | I1329: 70 | J1329: =I1329/$J$1*($J$1-$E$1) -> 65.333333 | K1329: 0 | L1329: =I1329-K1329 -> 70 | M1329: =IFERROR((K1329/J1329%),"-") -> 0 | N1329: 0 | O1329: =IF(F1329<=$P$2,"Mar","") -> Mar | P1329: =N1329 -> 0 | Q1329: =K1329-P1329 -> 0 | R1329: =IFERROR(IF(O1329="Mar",(K1329/P1329-1))," ") | S1329: =IF(N1329>0,IF(O1329="","-",IF(R1329<0%,"DEGROWTH","GROWTH"))) -> FALSE | T1329: 60 | U1329: =IF(F1329<=$V$2,"Apr","") -> Apr | V1329: 60 | W1329: =K1329-V1329 -> -60 | X1329: =IFERROR(IF(U1329="Apr",(K1329/V1329-1)),0) -> -1 | Y1329: =IF(T1329>0,IF(U1329="","-",IF(X1329<0%,"DEGROWTH","GROWTH"))) -> DEGROWTH | Z1329: 0 | AB1329: NE 1 | AC1329: NE 1 | AD1329: =IF(K1329=0,1,0) -> 1
